Workbook

Sheet 副主任&工艺组长及其他
A1: 车间 | B1: 职务 | C1: 姓名 | D1: 员工编号 | E1: 入职日期 | F1: 实际奖金合计 | G1: 日常巡查扣款 | H1: 记录巡查扣款 | I1: 定点摄影最佳区域和最差区域评比 | J1: 奖惩 | K1: 出勤率 | L1: 调整后奖金 | M1: 调整后档位 | N1: 基础挡位 | O1: 计件批次 （参考） | P1: 设备体积利用率 | Q1: 备注
A2: 寡核苷酸厂房1D级区域 | B2: 副主任 | C2: 刘震 | D2: ALS1988 | E2: 42073 | F2: =(L2*K2+G2+H2+I2-J2) -> 600 | G2: =SUMIF(积分汇总!$B:$B,'副主任&工艺组长及其他'!C2,积分汇总!$E:$E) -> 0 | H2: =SUMIF(记录巡查问题条数汇总!$B:$B,'副主任&工艺组长及其他'!C2,记录巡查问题条数汇总!$E:$E) -> 0 | J2: =SUMIF(安全质量事故!$B:$B,'副主任&工艺组长及其他'!C2,安全质量事故!$G:$G) -> 0 | K2: 1 | L2: =HLOOKUP(M2,$A$143:$H$144,2) -> 600 | M2: A | N2: B | O2: 201.08 | P2: 0.539
A3: 寡核苷酸厂房1D级区域 | B3: 副主任 | C3: 王鑫 | D3: ALS8215 | E3: 44431 | F3: =(L3*K3+G3+H3+I3-J3) -> 600 | G3: =SUMIF(积分汇总!$B:$B,'副主任&工艺组长及其他'!C3,积分汇总!$E:$E) -> 0 | H3: =SUMIF(记录巡查问题条数汇总!$B:$B,'副主任&工艺组长及其他'!C3,记录巡查问题条数汇总!$E:$E) -> 0 | J3: =SUMIF(安全质量事故!$B:$B,'副主任&工艺组长及其他'!C3,安全质量事故!$G:$G) -> 0 | K3: 1 | L3: =HLOOKUP(M3,$A$143:$H$144,2) -> 600 | M3: A
A4: 寡核苷酸厂房1D级区域 | B4: 副主任 | C4: 胡强 | D4: ALS10148 | E4: 44755 | F4: =(L4*K4+G4+H4+I4-J4) -> 400 | G4: =SUMIF(积分汇总!$B:$B,'副主任&工艺组长及其他'!C4,积分汇总!$E:$E) -> 0 | H4: =SUMIF(记录巡查问题条数汇总!$B:$B,'副主任&工艺组长及其他'!C4,记录巡查问题条数汇总!$E:$E) -> 0 | J4: =SUMIF(安全质量事故!$B:$B,'副主任&工艺组长及其他'!C4,安全质量事故!$G:$G) -> 0 | K4: 1 | L4: =HLOOKUP(M4,$A$143:$H$144,2) -> 400 | M4: B
A5: 寡核苷酸厂房1D级区域 | B5: 工艺组长 | C5: 白春江 | D5: FX2679 | E5: 42933 | F5: =(L5*K5+G5+H5+I5-J5) -> 600 | G5: =SUMIF(积分汇总!$B:$B,'副主任&工艺组长及其他'!C5,积分汇总!$E:$E) -> 0 | H5: =SUMIF(记录巡查问题条数汇总!$B:$B,'副主任&工艺组长及其他'!C5,记录巡查问题条数汇总!$E:$E) -> 0 | J5: =SUMIF(安全质量事故!$B:$B,'副主任&工艺组长及其他'!C5,安全质量事故!$G:$G) -> 0 | K5: 1 | L5: =HLOOKUP(M5,$A$143:$H$144,2) -> 600 | M5: A
A6: 寡核苷酸厂房1D级区域 | B6: 工艺组长 | C6: 罗林 | D6: ADH5191 | E6: 44677 | F6: =(L6*K6+G6+H6+I6-J6) -> 600 | G6: =SUMIF(积分汇总!$B:$B,'副主任&工艺组长及其他'!C6,积分汇总!$E:$E) -> 0 | H6: =SUMIF(记录巡查问题条数汇总!$B:$B,'副主任&工艺组长及其他'!C6,记录巡查问题条数汇总!$E:$E) -> 0 | J6: =SUMIF(安全质量事故!$B:$B,'副主任&工艺组长及其他'!C6,安全质量事故!$G:$G) -> 0 | K6: 1 | L6: =HLOOKUP(M6,$A$143:$H$144,2) -> 600 | M6: A
A7: 寡核苷酸厂房1D级区域 | B7: 工艺组长 | C7: 韩智慧 | D7: ALS10146 | E7: 44755 | F7: =(L7*K7+G7+H7+I7-J7) -> 400 | G7: =SUMIF(积分汇总!$B:$B,'副主任&工艺组长及其他'!C7,积分汇总!$E:$E) -> 0 | H7: =SUMIF(记录巡查问题条数汇总!$B:$B,'副主任&工艺组长及其他'!C7,记录巡查问题条数汇总!$E:$E) -> 0 | J7: =SUMIF(安全质量事故!$B:$B,'副主任&工艺组长及其他'!C7,安全质量事故!$G:$G) -> 0 | K7: 1 | L7: =HLOOKUP(M7,$A$143:$H$144,2) -> 400 | M7: B
A8: 寡核苷酸厂房1D级区域 | B8: 工艺组长 | C8: 陈雍 | D8: BDH0641 | E8: 44732 | F8: =(L8*K8+G8+H8+I8-J8) -> 400 | G8: =SUMIF(积分汇总!$B:$B,'副主任&工艺组长及其他'!C8,积分汇总!$E:$E) -> 0 | H8: =SUMIF(记录巡查问题条数汇总!$B:$B,'副主任&工艺组长及其他'!C8,记录巡查问题条数汇总!$E:$E) -> 0 | J8: =SUMIF(安全质量事故!$B:$B,'副主任&工艺组长及其他'!C8,安全质量事故!$G:$G) -> 0 | K8: 1 | L8: =HLOOKUP(M8,$A$143:$H$144,2) -> 400 | M8: B
A9: 寡核苷酸厂房1D级区域 | B9: 工艺组长 | C9: 孙福林 | D9: ALS16047 | E9: 46057 | F9: =(L9*K9+G9+H9+I9-J9) -> 400 | G9: =SUMIF(积分汇总!$B:$B,'副主任&工艺组长及其他'!C9,积分汇总!$E:$E) -> 0 | H9: =SUMIF(记录巡查问题条数汇总!$B:$B,'副主任&工艺组长及其他'!C9,记录巡查问题条数汇总!$E:$E) -> 0 | J9: =SUMIF(安全质量事故!$B:$B,'副主任&工艺组长及其他'!C9,安全质量事故!$G:$G) -> 0 | K9: 1 | L9: =HLOOKUP(M9,$A$143:$H$144,2) -> 400 | M9: B
A10: 寡核苷酸厂房1D级区域 | B10: 工艺组长 | C10: 陈博文 | D10: ALS7875 | E10: 44389 | F10: =(L10*K10+G10+H10+I10-J10) -> 400 | G10: =SUMIF(积分汇总!$B:$B,'副主任&工艺组长及其他'!C10,积分汇总!$E:$E) -> 0 | H10: =SUMIF(记录巡查问题条数汇总!$B:$B,'副主任&工艺组长及其他'!C10,记录巡查问题条数汇总!$E:$E) -> 0 | J10: =SUMIF(安全质量事故!$B:$B,'副主任&工艺组长及其他'!C10,安全质量事故!$G:$G) -> 0 | K10: 1 | L10: =HLOOKUP(M10,$A$143:$H$144,2) -> 400 | M10: B
A11: 寡核苷酸厂房1CNC区域 | B11: 副主任 | C11: 王家伟 | D11: ACT2027 | E11: 44125 | F11: =(L11*K11+G11+H11+I11-J11) -> 600 | G11: =SUMIF(积分汇总!$B:$B,'副主任&工艺组长及其他'!C11,积分汇总!$E:$E) -> 0 | H11: =SUMIF(记录巡查问题条数汇总!$B:$B,'副主任&工艺组长及其他'!C11,记录巡查问题条数汇总!$E:$E) -> 0 | J11: =SUMIF(安全质量事故!$B:$B,'副主任&工艺组长及其他'!C11,安全质量事故!$G:$G) -> 0 | K11: 1 | L11: =HLOOKUP(M11,$A$143:$H$144,2) -> 600 | M11: A
A12: 寡核苷酸厂房1CNC区域 | B12: 副主任 | C12: 杨欢 | D12: ALS7213 | E12: 44272 | F12: =(L12*K12+G12+H12+I12-J12) -> 400 | G12: =SUMIF(积分汇总!$B:$B,'副主任&工艺组长及其他'!C12,积分汇总!$E:$E) -> 0 | H12: =SUMIF(记录巡查问题条数汇总!$B:$B,'副主任&工艺组长及其他'!C12,记录巡查问题条数汇总!$E:$E) -> 0 | J12: =SUMIF(安全质量事故!$B:$B,'副主任&工艺组长及其他'!C12,安全质量事故!$G:$G) -> 0 | K12: 1 | L12: =HLOOKUP(M12,$A$143:$H$144,2) -> 400 | M12: B
A13: 寡核苷酸厂房1CNC区域 | B13: 副主任 | C13: 李国强 | D13: ALS6830 | E13: 44139 | F13: =(L13*K13+G13+H13+I13-J13) -> 600 | G13: =SUMIF(积分汇总!$B:$B,'副主任&工艺组长及其他'!C13,积分汇总!$E:$E) -> 0 | H13: =SUMIF(记录巡查问题条数汇总!$B:$B,'副主任&工艺组长及其他'!C13,记录巡查问题条数汇总!$E:$E) -> 0 | J13: =SUMIF(安全质量事故!$B:$B,'副主任&工艺组长及其他'!C13,安全质量事故!$G:$G) -> 0 | K13: 1 | L13: =HLOOKUP(M13,$A$143:$H$144,2) -> 600 | M13: A
A14: 寡核苷酸厂房1CNC区域 | B14: 副主任 | C14: 张华 | D14: ALS18404 | E14: 46253 | F14: =(L14*K14+G14+H14+I14-J14) -> 77.419355 | G14: =SUMIF(积分汇总!$B:$B,'副主任&工艺组长及其他'!C14,积分汇总!$E:$E) -> 0 | H14: =SUMIF(记录巡查问题条数汇总!$B:$B,'副主任&工艺组长及其他'!C14,记录巡查问题条数汇总!$E:$E) -> 0 | J14: =SUMIF(安全质量事故!$B:$B,'副主任&工艺组长及其他'!C14,安全质量事故!$G:$G) -> 0 | K14: =12/31 -> 0.38709677 | L14: =HLOOKUP(M14,$A$143:$H$144,2) -> 200 | M14: C
A15: 寡核苷酸厂房1CNC区域 | B15: 工艺组长 | C15: 朱晔 | D15: ALS3598 | E15: 42926 | F15: =(L15*K15+G15+H15+I15-J15) -> 600 | G15: =SUMIF(积分汇总!$B:$B,'副主任&工艺组长及其他'!C15,积分汇总!$E:$E) -> 0 | H15: =SUMIF(记录巡查问题条数汇总!$B:$B,'副主任&工艺组长及其他'!C15,记录巡查问题条数汇总!$E:$E) -> 0 | J15: =SUMIF(安全质量事故!$B:$B,'副主任&工艺组长及其他'!C15,安全质量事故!$G:$G) -> 0 | K15: 1 | L15: =HLOOKUP(M15,$A$143:$H$144,2) -> 600 | M15: A
A16: 寡核苷酸厂房1CNC区域 | B16: 工艺组长 | C16: 郭纹建 | D16: FX2691 | E16: 42972 | F16: =(L16*K16+G16+H16+I16-J16) -> 400 | G16: =SUMIF(积分汇总!$B:$B,'副主任&工艺组长及其他'!C16,积分汇总!$E:$E) -> 0 | H16: =SUMIF(记录巡查问题条数汇总!$B:$B,'副主任&工艺组长及其他'!C16,记录巡查问题条数汇总!$E:$E) -> 0 | J16: =SUMIF(安全质量事故!$B:$B,'副主任&工艺组长及其他'!C16,安全质量事故!$G:$G) -> 0 | K16: 1 | L16: =HLOOKUP(M16,$A$143:$H$144,2) -> 400 | M16: B
A17: 寡核苷酸厂房1CNC区域 | B17: 工艺组长 | C17: 刘旺 | D17: ALS10155 | E17: 44755 | F17: =(L17*K17+G17+H17+I17-J17) -> 600 | G17: =SUMIF(积分汇总!$B:$B,'副主任&工艺组长及其他'!C17,积分汇总!$E:$E) -> 0 | H17: =SUMIF(记录巡查问题条数汇总!$B:$B,'副主任&工艺组长及其他'!C17,记录巡查问题条数汇总!$E:$E) -> 0 | J17: =SUMIF(安全质量事故!$B:$B,'副主任&工艺组长及其他'!C17,安全质量事故!$G:$G) -> 0 | K17: 1 | L17: =HLOOKUP(M17,$A$143:$H$144,2) -> 600 | M17: A
A18: 寡核苷酸厂房1CNC区域 | B18: 工艺组长 | C18: 晏和聪 | D18: ALS10332 | E18: 44734 | F18: =(L18*K18+G18+H18+I18-J18) -> 400 | G18: =SUMIF(积分汇总!$B:$B,'副主任&工艺组长及其他'!C18,积分汇总!$E:$E) -> 0 | H18: =SUMIF(记录巡查问题条数汇总!$B:$B,'副主任&工艺组长及其他'!C18,记录巡查问题条数汇总!$E:$E) -> 0 | J18: =SUMIF(安全质量事故!$B:$B,'副主任&工艺组长及其他'!C18,安全质量事故!$G:$G) -> 0 | K18: 1 | L18: =HLOOKUP(M18,$A$143:$H$144,2) -> 400 | M18: B
A19: 寡核苷酸厂房1CNC区域 | B19: 工艺组长 | C19: 李天宇 | D19: ALS10153 | E19: 44755 | F19: =(L19*K19+G19+H19+I19-J19) -> 600 | G19: =SUMIF(积分汇总!$B:$B,'副主任&工艺组长及其他'!C19,积分汇总!$E:$E) -> 0 | H19: =SUMIF(记录巡查问题条数汇总!$B:$B,'副主任&工艺组长及其他'!C19,记录巡查问题条数汇总!$E:$E) -> 0 | J19: =SUMIF(安全质量事故!$B:$B,'副主任&工艺组长及其他'!C19,安全质量事故!$G:$G) -> 0 | K19: 1 | L19: =HLOOKUP(M19,$A$143:$H$144,2) -> 600 | M19: A
A20: 寡核苷酸厂房1CNC区域 | B20: 工艺组长 | C20: 谢文忠 | D20: ALS8245 | E20: 44433 | F20: =(L20*K20+G20+H20+I20-J20) -> 400 | G20: =SUMIF(积分汇总!$B:$B,'副主任&工艺组长及其他'!C20,积分汇总!$E:$E) -> 0 | H20: =SUMIF(记录巡查问题条数汇总!$B:$B,'副主任&工艺组长及其他'!C20,记录巡查问题条数汇总!$E:$E) -> 0 | J20: =SUMIF(安全质量事故!$B:$B,'副主任&工艺组长及其他'!C20,安全质量事故!$G:$G) -> 0 | K20: 1 | L20: =HLOOKUP(M20,$A$143:$H$144,2) -> 400 | M20: B
A21: 寡核苷酸厂房1CNC区域 | B21: 工艺组长 | C21: 曹佳乐 | D21: ALS10142 | E21: 44755 | F21: =(L21*K21+G21+H21+I21-J21) -> 400 | G21: =SUMIF(积分汇总!$B:$B,'副主任&工艺组长及其他'!C21,积分汇总!$E:$E) -> 0 | H21: =SUMIF(记录巡查问题条数汇总!$B:$B,'副主任&工艺组长及其他'!C21,记录巡查问题条数汇总!$E:$E) -> 0 | J21: =SUMIF(安全质量事故!$B:$B,'副主任&工艺组长及其他'!C21,安全质量事故!$G:$G) -> 0 | K21: 1 | L21: =HLOOKUP(M21,$A$143:$H$144,2) -> 400 | M21: B
A22: 寡核苷酸厂房1CNC区域 | B22: 工艺组长 | C22: 刘运峰 | D22: ALS14684 | E22: 45889 | F22: =(L22*K22+G22+H22+I22-J22) -> 400 | G22: =SUMIF(积分汇总!$B:$B,'副主任&工艺组长及其他'!C22,积分汇总!$E:$E) -> 0 | H22: =SUMIF(记录巡查问题条数汇总!$B:$B,'副主任&工艺组长及其他'!C22,记录巡查问题条数汇总!$E:$E) -> 0 | J22: =SUMIF(安全质量事故!$B:$B,'副主任&工艺组长及其他'!C22,安全质量事故!$G:$G) -> 0 | K22: 1 | L22: =HLOOKUP(M22,$A$143:$H$144,2) -> 400 | M22: B
A23: 寡核苷酸厂房1CNC区域 | B23: 工艺组长 | C23: 谢红彬 | D23: ALS16022 | E23: 46050 | F23: =(L23*K23+G23+H23+I23-J23) -> 400 | G23: =SUMIF(积分汇总!$B:$B,'副主任&工艺组长及其他'!C23,积分汇总!$E:$E) -> 0 | H23: =SUMIF(记录巡查问题条数汇总!$B:$B,'副主任&工艺组长及其他'!C23,记录巡查问题条数汇总!$E:$E) -> 0 | J23: =SUMIF(安全质量事故!$B:$B,'副主任&工艺组长及其他'!C23,安全质量事故!$G:$G) -> 0 | K23: 1 | L23: =HLOOKUP(M23,$A$143:$H$144,2) -> 400 | M23: B
A24: 多肽厂房1CNC区域 | B24: 副主任 | C24: 安林波 | D24: ACT844 | E24: 38803 | F24: =(L24*K24+G24+H24+I24-J24) -> 400 | G24: =SUMIF(积分汇总!$B:$B,'副主任&工艺组长及其他'!C24,积分汇总!$E:$E) -> 0 | H24: =SUMIF(记录巡查问题条数汇总!$B:$B,'副主任&工艺组长及其他'!C24,记录巡查问题条数汇总!$E:$E) -> 0 | J24: =SUMIF(安全质量事故!$B:$B,'副主任&工艺组长及其他'!C24,安全质量事故!$G:$G) -> 0 | K24: 1 | L24: =HLOOKUP(M24,$A$143:$H$144,2) -> 400 | M24: B | N24: B | O24: 95.26 | P24: 0.523
A25: 多肽厂房1CNC区域 | B25: 副主任 | C25: 王仁君 | D25: ALS17929 | E25: 46213 | F25: =(L25*K25+G25+H25+I25-J25) -> 200 | G25: =SUMIF(积分汇总!$B:$B,'副主任&工艺组长及其他'!C25,积分汇总!$E:$E) -> 0 | H25: =SUMIF(记录巡查问题条数汇总!$B:$B,'副主任&工艺组长及其他'!C25,记录巡查问题条数汇总!$E:$E) -> 0 | J25: =SUMIF(安全质量事故!$B:$B,'副主任&工艺组长及其他'!C25,安全质量事故!$G:$G) -> 0 | K25: 1 | L25: =HLOOKUP(M25,$A$143:$H$144,2) -> 200 | M25: C
A26: 多肽厂房1CNC区域 | B26: 工艺组长 | C26: 付闯闯 | D26: ALS11094 | E26: 44774 | F26: =(L26*K26+G26+H26+I26-J26) -> 400 | G26: =SUMIF(积分汇总!$B:$B,'副主任&工艺组长及其他'!C26,积分汇总!$E:$E) -> 0 | H26: =SUMIF(记录巡查问题条数汇总!$B:$B,'副主任&工艺组长及其他'!C26,记录巡查问题条数汇总!$E:$E) -> 0 | J26: =SUMIF(安全质量事故!$B:$B,'副主任&工艺组长及其他'!C26,安全质量事故!$G:$G) -> 0 | K26: 1 | L26: =HLOOKUP(M26,$A$143:$H$144,2) -> 400 | M26: B
A27: 多肽厂房1CNC区域 | B27: 工艺组长 | C27: 侯长恺 | D27: ALS18335 | E27: 46246 | F27: =(L27*K27+G27+H27+I27-J27) -> 122.58065 | G27: =SUMIF(积分汇总!$B:$B,'副主任&工艺组长及其他'!C27,积分汇总!$E:$E) -> 0 | H27: =SUMIF(记录巡查问题条数汇总!$B:$B,'副主任&工艺组长及其他'!C27,记录巡查问题条数汇总!$E:$E) -> 0 | J27: =SUMIF(安全质量事故!$B:$B,'副主任&工艺组长及其他'!C27,安全质量事故!$G:$G) -> 0 | K27: =19/31 -> 0.61290323 | L27: =HLOOKUP(M27,$A$143:$H$144,2) -> 200 | M27: C
A28: 多肽厂房1CNC区域 | B28: 工艺组长 | C28: 李程 | D28: ALS18264 | E28: 46239 | F28: =(L28*K28+G28+H28+I28-J28) -> 167.74194 | G28: =SUMIF(积分汇总!$B:$B,'副主任&工艺组长及其他'!C28,积分汇总!$E:$E) -> 0 | H28: =SUMIF(记录巡查问题条数汇总!$B:$B,'副主任&工艺组长及其他'!C28,记录巡查问题条数汇总!$E:$E) -> 0 | J28: =SUMIF(安全质量事故!$B:$B,'副主任&工艺组长及其他'!C28,安全质量事故!$G:$G) -> 0 | K28: =26/31 -> 0.83870968 | L28: =HLOOKUP(M28,$A$143:$H$144,2) -> 200 | M28: C
A29: 多肽厂房1CNC区域 | B29: 工程师 | C29: 李祥杰 | D29: ALS17331 | E29: 46215 | F29: =(L29*K29+G29+H29+I29-J29) -> 200 | G29: =SUMIF(积分汇总!$B:$B,'副主任&工艺组长及其他'!C29,积分汇总!$E:$E) -> 0 | H29: =SUMIF(记录巡查问题条数汇总!$B:$B,'副主任&工艺组长及其他'!C29,记录巡查问题条数汇总!$E:$E) -> 0 | J29: =SUMIF(安全质量事故!$B:$B,'副主任&工艺组长及其他'!C29,安全质量事故!$G:$G) -> 0 | K29: 1 | L29: =HLOOKUP(M29,$A$143:$H$144,2) -> 200 | M29: C
A30: 多肽厂房1CNC区域 | B30: 助理工程师 | C30: 杨泉斌 | D30: ALS14338 | E30: 45847 | F30: =(L30*K30+G30+H30+I30-J30) -> 400 | G30: =SUMIF(积分汇总!$B:$B,'副主任&工艺组长及其他'!C30,积分汇总!$E:$E) -> 0 | H30: =SUMIF(记录巡查问题条数汇总!$B:$B,'副主任&工艺组长及其他'!C30,记录巡查问题条数汇总!$E:$E) -> 0 | J30: =SUMIF(安全质量事故!$B:$B,'副主任&工艺组长及其他'!C30,安全质量事故!$G:$G) -> 0 | K30: 1 | L30: =HLOOKUP(M30,$A$143:$H$144,2) -> 400 | M30: B
A31: 多肽厂房1D级区域 | B31: 副主任 | C31: 柯圣涛 | D31: ALS15385 | E31: 45980 | F31: =(L31*K31+G31+H31+I31-J31) -> 400 | G31: =SUMIF(积分汇总!$B:$B,'副主任&工艺组长及其他'!C31,积分汇总!$E:$E) -> 0 | H31: =SUMIF(记录巡查问题条数汇总!$B:$B,'副主任&工艺组长及其他'!C31,记录巡查问题条数汇总!$E:$E) -> 0 | J31: =SUMIF(安全质量事故!$B:$B,'副主任&工艺组长及其他'!C31,安全质量事故!$G:$G) -> 0 | K31: 1 | L31: =HLOOKUP(M31,$A$143:$H$144,2) -> 400 | M31: B
A32: 多肽厂房1D级区域 | B32: 副主任 | C32: 林志广 | D32: ALS15602 | E32: 46001 | F32: =(L32*K32+G32+H32+I32-J32) -> 400 | G32: =SUMIF(积分汇总!$B:$B,'副主任&工艺组长及其他'!C32,积分汇总!$E:$E) -> 0 | H32: =SUMIF(记录巡查问题条数汇总!$B:$B,'副主任&工艺组长及其他'!C32,记录巡查问题条数汇总!$E:$E) -> 0 | J32: =SUMIF(安全质量事故!$B:$B,'副主任&工艺组长及其他'!C32,安全质量事故!$G:$G) -> 0 | K32: 1 | L32: =HLOOKUP(M32,$A$143:$H$144,2) -> 400 | M32: B
A33: 多肽厂房1D级区域 | B33: 副主任 | C33: 崔涛 | D33: ALS16861 | E33: 46162 | F33: =(L33*K33+G33+H33+I33-J33) -> 400 | G33: =SUMIF(积分汇总!$B:$B,'副主任&工艺组长及其他'!C33,积分汇总!$E:$E) -> 0 | H33: =SUMIF(记录巡查问题条数汇总!$B:$B,'副主任&工艺组长及其他'!C33,记录巡查问题条数汇总!$E:$E) -> 0 | J33: =SUMIF(安全质量事故!$B:$B,'副主任&工艺组长及其他'!C33,安全质量事故!$G:$G) -> 0 | K33: 1 | L33: =HLOOKUP(M33,$A$143:$H$144,2) -> 400 | M33: B
A34: 多肽厂房1D级区域 | B34: 副主任 | C34: 程帅 | D34: ALS17522 | E34: 46204 | F34: =(L34*K34+G34+H34+I34-J34) -> 200 | G34: =SUMIF(积分汇总!$B:$B,'副主任&工艺组长及其他'!C34,积分汇总!$E:$E) -> 0 | H34: =SUMIF(记录巡查问题条数汇总!$B:$B,'副主任&工艺组长及其他'!C34,记录巡查问题条数汇总!$E:$E) -> 0 | J34: =SUMIF(安全质量事故!$B:$B,'副主任&工艺组长及其他'!C34,安全质量事故!$G:$G) -> 0 | K34: 1 | L34: =HLOOKUP(M34,$A$143:$H$144,2) -> 200 | M34: C
A35: 多肽厂房1D级区域 | B35: 副主任 | C35: 高峰 | D35: ALS18194 | E35: 46232 | F35: =(L35*K35+G35+H35+I35-J35) -> 200 | G35: =SUMIF(积分汇总!$B:$B,'副主任&工艺组长及其他'!C35,积分汇总!$E:$E) -> 0 | H35: =SUMIF(记录巡查问题条数汇总!$B:$B,'副主任&工艺组长及其他'!C35,记录巡查问题条数汇总!$E:$E) -> 0 | J35: =SUMIF(安全质量事故!$B:$B,'副主任&工艺组长及其他'!C35,安全质量事故!$G:$G) -> 0 | K35: 1 | L35: =HLOOKUP(M35,$A$143:$H$144,2) -> 200 | M35: C
A36: 多肽厂房1D级区域 | B36: 工艺组长 | C36: 王兴 | D36: ALS17895 | E36: 46213 | F36: =(L36*K36+G36+H36+I36-J36) -> 200 | G36: =SUMIF(积分汇总!$B:$B,'副主任&工艺组长及其他'!C36,积分汇总!$E:$E) -> 0 | H36: =SUMIF(记录巡查问题条数汇总!$B:$B,'副主任&工艺组长及其他'!C36,记录巡查问题条数汇总!$E:$E) -> 0 | J36: =SUMIF(安全质量事故!$B:$B,'副主任&工艺组长及其他'!C36,安全质量事故!$G:$G) -> 0 | K36: 1 | L36: =HLOOKUP(M36,$A$143:$H$144,2) -> 200 | M36: C
A37: 多肽厂房1D级区域 | B37: 工艺组长 | C37: 张睿尧 | D37: ALS12615 | E37: 45194 | F37: =(L37*K37+G37+H37+I37-J37) -> 400 | G37: =SUMIF(积分汇总!$B:$B,'副主任&工艺组长及其他'!C37,积分汇总!$E:$E) -> 0 | H37: =SUMIF(记录巡查问题条数汇总!$B:$B,'副主任&工艺组长及其他'!C37,记录巡查问题条数汇总!$E:$E) -> 0 | J37: =SUMIF(安全质量事故!$B:$B,'副主任&工艺组长及其他'!C37,安全质量事故!$G:$G) -> 0 | K37: 1 | L37: =HLOOKUP(M37,$A$143:$H$144,2) -> 400 | M37: B
A38: 多肽厂房1D级区域 | B38: 工程师 | C38: 刘贵祥 | D38: ALS15494 | E38: 45992 | F38: =(L38*K38+G38+H38+I38-J38) -> 400 | G38: =SUMIF(积分汇总!$B:$B,'副主任&工艺组长及其他'!C38,积分汇总!$E:$E) -> 0 | H38: =SUMIF(记录巡查问题条数汇总!$B:$B,'副主任&工艺组长及其他'!C38,记录巡查问题条数汇总!$E:$E) -> 0 | J38: =SUMIF(安全质量事故!$B:$B,'副主任&工艺组长及其他'!C38,安全质量事故!$G:$G) -> 0 | K38: 1 | L38: =HLOOKUP(M38,$A$143:$H$144,2) -> 400 | M38: B
A39: 多肽厂房1D级区域 | B39: 助理工程师 | C39: 郭佳祥 | D39: ALS13034 | E39: 45469 | F39: =(L39*K39+G39+H39+I39-J39) -> 400 | G39: =SUMIF(积分汇总!$B:$B,'副主任&工艺组长及其他'!C39,积分汇总!$E:$E) -> 0 | H39: =SUMIF(记录巡查问题条数汇总!$B:$B,'副主任&工艺组长及其他'!C39,记录巡查问题条数汇总!$E:$E) -> 0 | J39: =SUMIF(安全质量事故!$B:$B,'副主任&工艺组长及其他'!C39,安全质量事故!$G:$G) -> 0 | K39: 1 | L39: =HLOOKUP(M39,$A$143:$H$144,2) -> 400 | M39: B | Q39: 2025/10/27调实验室学习制备
A40: 多肽厂房1D级区域 | B40: 助理工程师 | C40: 郭硕 | D40: ALS16547 | E40: 46134 | F40: =(L40*K40+G40+H40+I40-J40) -> 400 | G40: =SUMIF(积分汇总!$B:$B,'副主任&工艺组长及其他'!C40,积分汇总!$E:$E) -> 0 | H40: =SUMIF(记录巡查问题条数汇总!$B:$B,'副主任&工艺组长及其他'!C40,记录巡查问题条数汇总!$E:$E) -> 0 | J40: =SUMIF(安全质量事故!$B:$B,'副主任&工艺组长及其他'!C40,安全质量事故!$G:$G) -> 0 | K40: 1 | L40: =HLOOKUP(M40,$A$143:$H$144,2) -> 400 | M40: B | Q40: 师傅 杨欢；2026/05/06调实验室学习制备
...

Sheet 一线人员
F1: =SUM(F100:F1451) -> 0
A2: 车间 | B2: 职务 | C2: 姓名 | D2: 员工编号 | E2: 入职日期 | F2: 实际奖金合计 | G2: 日常巡查扣款 | H2: 记录巡查扣款 | I2: 定点摄影最佳区域和最差区域评比 | J2: 安全事故扣款 | K2: 5S日检奖金合计 | L2: 09月
L3: 46266 | M3: 46267 | N3: 46268 | O3: 46269 | P3: 46270 | Q3: 46271 | R3: 46272 | S3: 46273 | T3: 46274 | U3: 46275 | V3: 46276 | W3: 46277 | X3: 46278 | Y3: 46279 | Z3: 46280 | AA3: 46281 | AB3: 46282 | AC3: 46283 | AD3: 46284 | AE3: 46285 | AF3: 46286 | AG3: 46287 | AH3: 46288 | AI3: 46289 | AJ3: 46290 | AK3: 46291 | AL3: 46292 | AM3: 46293 | AN3: 46294 | AO3: 46295 | AP3: 46296 | AQ3: 备注 | AU3: 核对1 | AV3: 核对2
A4: 寡核苷酸厂房1CNC区域 | B4: 助工 | C4: 李军宝 | D4: ALS17425 | E4: 46215 | F4: =(K4+G4+H4+I4-J4) -> 0 | G4: =SUMIF(积分汇总!$B:$B,#REF!,积分汇总!$E:$E) -> 0 | H4: =SUMIF(记录巡查问题条数汇总!$B:$B,#REF!,记录巡查问题条数汇总!$E:$E) -> 0 | J4: =SUMIF(安全质量事故!$B:$B,#REF!,安全质量事故!$G:$G) -> 0 | K4: =COUNTIF(L4:AP4,标准数据!$A$2)*标准数据!$B$2+COUNTIF(L4:AP4,标准数据!$A$3)*标准数据!$B$3+COUNTIF(L4:AP4,标准数据!$A$4)*标准数据!$B$4 -> 0 | AR4: 寡核苷酸厂房1CNC区域“a、b、c”分布情况
A5: 寡核苷酸厂房1CNC区域 | B5: 助工 | C5: 闫津铭 | D5: ALS17438 | E5: 46215 | F5: =(K5+G5+H5+I5-J5) -> 0 | G5: =SUMIF(积分汇总!$B:$B,C4,积分汇总!$E:$E) -> 0 | H5: =SUMIF(记录巡查问题条数汇总!$B:$B,C4,记录巡查问题条数汇总!$E:$E) -> 0 | J5: =SUMIF(安全质量事故!$B:$B,C4,安全质量事故!$G:$G) -> 0 | K5: =COUNTIF(L5:AP5,标准数据!$A$2)*标准数据!$B$2+COUNTIF(L5:AP5,标准数据!$A$3)*标准数据!$B$3+COUNTIF(L5:AP5,标准数据!$A$4)*标准数据!$B$4 -> 0 | AR5: “a”占比 | AS5: “b”占比 | AT5: “c”占比
A6: 寡核苷酸厂房1CNC区域 | B6: 助工 | C6: 朱义龙 | D6: ALS17421 | E6: 46215 | F6: =(K6+G6+H6+I6-J6) -> 0 | G6: =SUMIF(积分汇总!$B:$B,C5,积分汇总!$E:$E) -> 0 | H6: =SUMIF(记录巡查问题条数汇总!$B:$B,C5,记录巡查问题条数汇总!$E:$E) -> 0 | J6: =SUMIF(安全质量事故!$B:$B,C5,安全质量事故!$G:$G) -> 0 | K6: =COUNTIF(L6:AP6,标准数据!$A$2)*标准数据!$B$2+COUNTIF(L6:AP6,标准数据!$A$3)*标准数据!$B$3+COUNTIF(L6:AP6,标准数据!$A$4)*标准数据!$B$4 -> 0 | AR6: =COUNTIF($L$4:$AP$99,"a") -> 0 | AS6: =COUNTIF($L$4:$AP$99,"b") -> 0 | AT6: =COUNTIF($L$4:$AP$99,"c") -> 0
A7: 寡核苷酸厂房1CNC区域 | B7: 助工 | C7: 陈志鸿 | D7: ALS17422 | E7: 46215 | F7: =(K7+G7+H7+I7-J7) -> 0 | G7: =SUMIF(积分汇总!$B:$B,C6,积分汇总!$E:$E) -> 0 | H7: =SUMIF(记录巡查问题条数汇总!$B:$B,C6,记录巡查问题条数汇总!$E:$E) -> 0 | J7: =SUMIF(安全质量事故!$B:$B,C6,安全质量事故!$G:$G) -> 0 | K7: =COUNTIF(L7:AP7,标准数据!$A$2)*标准数据!$B$2+COUNTIF(L7:AP7,标准数据!$A$3)*标准数据!$B$3+COUNTIF(L7:AP7,标准数据!$A$4)*标准数据!$B$4 -> 0 | AR7: =AR6/($AR$6+$AS$6+$AT$6) -> #DIV/0! | AS7: =AS6/($AR$6+$AS$6+$AT$6) -> #DIV/0! | AT7: =AT6/($AR$6+$AS$6+$AT$6) -> #DIV/0!
A8: 寡核苷酸厂房1CNC区域 | B8: 助工 | C8: 王云龙 | D8: ALS17435 | E8: 46215 | F8: =(K8+G8+H8+I8-J8) -> 0 | G8: =SUMIF(积分汇总!$B:$B,C7,积分汇总!$E:$E) -> 0 | H8: =SUMIF(记录巡查问题条数汇总!$B:$B,C7,记录巡查问题条数汇总!$E:$E) -> 0 | J8: =SUMIF(安全质量事故!$B:$B,C7,安全质量事故!$G:$G) -> 0 | K8: =COUNTIF(L8:AP8,标准数据!$A$2)*标准数据!$B$2+COUNTIF(L8:AP8,标准数据!$A$3)*标准数据!$B$3+COUNTIF(L8:AP8,标准数据!$A$4)*标准数据!$B$4 -> 0
A9: 寡核苷酸厂房1CNC区域 | B9: 助工 | C9: 焦文刚 | D9: ALS16988 | E9: 46169 | F9: =(K9+G9+H9+I9-J9) -> 0 | G9: =SUMIF(积分汇总!$B:$B,C8,积分汇总!$E:$E) -> 0 | H9: =SUMIF(记录巡查问题条数汇总!$B:$B,C8,记录巡查问题条数汇总!$E:$E) -> 0 | J9: =SUMIF(安全质量事故!$B:$B,C8,安全质量事故!$G:$G) -> 0 | K9: =COUNTIF(L9:AP9,标准数据!$A$2)*标准数据!$B$2+COUNTIF(L9:AP9,标准数据!$A$3)*标准数据!$B$3+COUNTIF(L9:AP9,标准数据!$A$4)*标准数据!$B$4 -> 0
A10: 寡核苷酸厂房1CNC区域 | B10: 助工 | C10: 李成波 | D10: ALS17357 | E10: 46215 | F10: =(K10+G10+H10+I10-J10) -> 0 | G10: =SUMIF(积分汇总!$B:$B,C8,积分汇总!$E:$E) -> 0 | H10: =SUMIF(记录巡查问题条数汇总!$B:$B,C8,记录巡查问题条数汇总!$E:$E) -> 0 | J10: =SUMIF(安全质量事故!$B:$B,C8,安全质量事故!$G:$G) -> 0 | K10: =COUNTIF(L10:AP10,标准数据!$A$2)*标准数据!$B$2+COUNTIF(L10:AP10,标准数据!$A$3)*标准数据!$B$3+COUNTIF(L10:AP10,标准数据!$A$4)*标准数据!$B$4 -> 0
A11: 寡核苷酸厂房1CNC区域 | B11: 操作工 | C11: 白鹏宇 | D11: ALS16434 | E11: 46127 | F11: =(K11+G11+H11+I11-J11) -> 0 | G11: =SUMIF(积分汇总!$B:$B,C10,积分汇总!$E:$E) -> 0 | H11: =SUMIF(记录巡查问题条数汇总!$B:$B,C10,记录巡查问题条数汇总!$E:$E) -> 0 | J11: =SUMIF(安全质量事故!$B:$B,C10,安全质量事故!$G:$G) -> 0 | K11: =COUNTIF(L11:AP11,标准数据!$A$2)*标准数据!$B$2+COUNTIF(L11:AP11,标准数据!$A$3)*标准数据!$B$3+COUNTIF(L11:AP11,标准数据!$A$4)*标准数据!$B$4 -> 0
A12: 寡核苷酸厂房1CNC区域 | B12: 工程师 | C12: 穆双超 | D12: ADH5432 | E12: 44752 | F12: =(K12+G12+H12+I12-J12) -> 0 | G12: =SUMIF(积分汇总!$B:$B,C11,积分汇总!$E:$E) -> 0 | H12: =SUMIF(记录巡查问题条数汇总!$B:$B,C11,记录巡查问题条数汇总!$E:$E) -> 0 | J12: =SUMIF(安全质量事故!$B:$B,C11,安全质量事故!$G:$G) -> 0 | K12: =COUNTIF(L12:AP12,标准数据!$A$2)*标准数据!$B$2+COUNTIF(L12:AP12,标准数据!$A$3)*标准数据!$B$3+COUNTIF(L12:AP12,标准数据!$A$4)*标准数据!$B$4 -> 0
A13: 寡核苷酸厂房1CNC区域 | B13: 工程师 | C13: 于清凡 | D13: ALS5619 | E13: 43677 | F13: =(K13+G13+H13+I13-J13) -> 0 | G13: =SUMIF(积分汇总!$B:$B,C12,积分汇总!$E:$E) -> 0 | H13: =SUMIF(记录巡查问题条数汇总!$B:$B,C12,记录巡查问题条数汇总!$E:$E) -> 0 | J13: =SUMIF(安全质量事故!$B:$B,C12,安全质量事故!$G:$G) -> 0 | K13: =COUNTIF(L13:AP13,标准数据!$A$2)*标准数据!$B$2+COUNTIF(L13:AP13,标准数据!$A$3)*标准数据!$B$3+COUNTIF(L13:AP13,标准数据!$A$4)*标准数据!$B$4 -> 0
A14: 寡核苷酸厂房1CNC区域 | B14: 工程师 | C14: 荣宪超 | D14: FX3085 | E14: 43977 | F14: =(K14+G14+H14+I14-J14) -> 0 | G14: =SUMIF(积分汇总!$B:$B,C13,积分汇总!$E:$E) -> 0 | H14: =SUMIF(记录巡查问题条数汇总!$B:$B,C13,记录巡查问题条数汇总!$E:$E) -> 0 | J14: =SUMIF(安全质量事故!$B:$B,C13,安全质量事故!$G:$G) -> 0 | K14: =COUNTIF(L14:AP14,标准数据!$A$2)*标准数据!$B$2+COUNTIF(L14:AP14,标准数据!$A$3)*标准数据!$B$3+COUNTIF(L14:AP14,标准数据!$A$4)*标准数据!$B$4 -> 0
A15: 寡核苷酸厂房1CNC区域 | B15: 工程师 | C15: 支庆 | D15: LFX569 | E15: 44389 | F15: =(K15+G15+H15+I15-J15) -> 0 | G15: =SUMIF(积分汇总!$B:$B,C14,积分汇总!$E:$E) -> 0 | H15: =SUMIF(记录巡查问题条数汇总!$B:$B,C14,记录巡查问题条数汇总!$E:$E) -> 0 | J15: =SUMIF(安全质量事故!$B:$B,C14,安全质量事故!$G:$G) -> 0 | K15: =COUNTIF(L15:AP15,标准数据!$A$2)*标准数据!$B$2+COUNTIF(L15:AP15,标准数据!$A$3)*标准数据!$B$3+COUNTIF(L15:AP15,标准数据!$A$4)*标准数据!$B$4 -> 0
A16: 寡核苷酸厂房1CNC区域 | B16: 工程师 | C16: 俞燕溪 | D16: ALS14328 | E16: 45847 | F16: =(K16+G16+H16+I16-J16) -> 0 | G16: =SUMIF(积分汇总!$B:$B,C15,积分汇总!$E:$E) -> 0 | H16: =SUMIF(记录巡查问题条数汇总!$B:$B,C15,记录巡查问题条数汇总!$E:$E) -> 0 | J16: =SUMIF(安全质量事故!$B:$B,C15,安全质量事故!$G:$G) -> 0 | K16: =COUNTIF(L16:AP16,标准数据!$A$2)*标准数据!$B$2+COUNTIF(L16:AP16,标准数据!$A$3)*标准数据!$B$3+COUNTIF(L16:AP16,标准数据!$A$4)*标准数据!$B$4 -> 0
A17: 寡核苷酸厂房1CNC区域 | B17: 工程师 | C17: 刘振 | D17: ALS16970 | E17: 46169 | F17: =(K17+G17+H17+I17-J17) -> 0 | G17: =SUMIF(积分汇总!$B:$B,C16,积分汇总!$E:$E) -> 0 | H17: =SUMIF(记录巡查问题条数汇总!$B:$B,C16,记录巡查问题条数汇总!$E:$E) -> 0 | J17: =SUMIF(安全质量事故!$B:$B,C16,安全质量事故!$G:$G) -> 0 | K17: =COUNTIF(L17:AP17,标准数据!$A$2)*标准数据!$B$2+COUNTIF(L17:AP17,标准数据!$A$3)*标准数据!$B$3+COUNTIF(L17:AP17,标准数据!$A$4)*标准数据!$B$4 -> 0
A18: 寡核苷酸厂房1CNC区域 | B18: 班长 | C18: 窦贤巩 | D18: ALS5807 | E18: 43817 | F18: =(K18+G18+H18+I18-J18) -> 0 | G18: =SUMIF(积分汇总!$B:$B,C17,积分汇总!$E:$E) -> 0 | H18: =SUMIF(记录巡查问题条数汇总!$B:$B,C17,记录巡查问题条数汇总!$E:$E) -> 0 | J18: =SUMIF(安全质量事故!$B:$B,C17,安全质量事故!$G:$G) -> 0 | K18: =COUNTIF(L18:AP18,标准数据!$A$2)*标准数据!$B$2+COUNTIF(L18:AP18,标准数据!$A$3)*标准数据!$B$3+COUNTIF(L18:AP18,标准数据!$A$4)*标准数据!$B$4 -> 0
A19: 寡核苷酸厂房1CNC区域 | B19: 班长 | C19: 李董明 | D19: ALS10327 | E19: 44734 | F19: =(K19+G19+H19+I19-J19) -> 0 | G19: =SUMIF(积分汇总!$B:$B,C18,积分汇总!$E:$E) -> 0 | H19: =SUMIF(记录巡查问题条数汇总!$B:$B,C18,记录巡查问题条数汇总!$E:$E) -> 0 | J19: =SUMIF(安全质量事故!$B:$B,C18,安全质量事故!$G:$G) -> 0 | K19: =COUNTIF(L19:AP19,标准数据!$A$2)*标准数据!$B$2+COUNTIF(L19:AP19,标准数据!$A$3)*标准数据!$B$3+COUNTIF(L19:AP19,标准数据!$A$4)*标准数据!$B$4 -> 0
A20: 寡核苷酸厂房1CNC区域 | B20: 班长 | C20: 王永乐 | D20: ALS10165 | E20: 44755 | F20: =(K20+G20+H20+I20-J20) -> 0 | G20: =SUMIF(积分汇总!$B:$B,C19,积分汇总!$E:$E) -> 0 | H20: =SUMIF(记录巡查问题条数汇总!$B:$B,C19,记录巡查问题条数汇总!$E:$E) -> 0 | J20: =SUMIF(安全质量事故!$B:$B,C19,安全质量事故!$G:$G) -> 0 | K20: =COUNTIF(L20:AP20,标准数据!$A$2)*标准数据!$B$2+COUNTIF(L20:AP20,标准数据!$A$3)*标准数据!$B$3+COUNTIF(L20:AP20,标准数据!$A$4)*标准数据!$B$4 -> 0
A21: 寡核苷酸厂房1CNC区域 | B21: 班长 | C21: 韩德玉 | D21: ALS11936 | E21: 45056 | F21: =(K21+G21+H21+I21-J21) -> 0 | G21: =SUMIF(积分汇总!$B:$B,C20,积分汇总!$E:$E) -> 0 | H21: =SUMIF(记录巡查问题条数汇总!$B:$B,C20,记录巡查问题条数汇总!$E:$E) -> 0 | J21: =SUMIF(安全质量事故!$B:$B,C20,安全质量事故!$G:$G) -> 0 | K21: =COUNTIF(L21:AP21,标准数据!$A$2)*标准数据!$B$2+COUNTIF(L21:AP21,标准数据!$A$3)*标准数据!$B$3+COUNTIF(L21:AP21,标准数据!$A$4)*标准数据!$B$4 -> 0
A22: 寡核苷酸厂房1CNC区域 | B22: 班长 | C22: 赵鹏帅 | D22: ALS10175 | E22: 44755 | F22: =(K22+G22+H22+I22-J22) -> 0 | G22: =SUMIF(积分汇总!$B:$B,C21,积分汇总!$E:$E) -> 0 | H22: =SUMIF(记录巡查问题条数汇总!$B:$B,C21,记录巡查问题条数汇总!$E:$E) -> 0 | J22: =SUMIF(安全质量事故!$B:$B,C21,安全质量事故!$G:$G) -> 0 | K22: =COUNTIF(L22:AP22,标准数据!$A$2)*标准数据!$B$2+COUNTIF(L22:AP22,标准数据!$A$3)*标准数据!$B$3+COUNTIF(L22:AP22,标准数据!$A$4)*标准数据!$B$4 -> 0
... A45: 寡核苷酸厂房1CNC区域 | B45: 助工 | C45: 张杰 | D45: ALS13442 | E45: 45546 | F45: =(K45+G45+H45+I45-J45) -> 0 | G45: =SUMIF(积分汇总!$B:$B,C44,积分汇总!$E:$E) -> 0 | H45: =SUMIF(记录巡查问题条数汇总!$B:$B,C44,记录巡查问题条数汇总!$E:$E) -> 0 | J45: =SUMIF(安全质量事故!$B:$B,C44,安全质量事故!$G:$G) -> 0 | K45: =COUNTIF(L45:AP45,标准数据!$A$2)*标准数据!$B$2+COUNTIF(L45:AP45,标准数据!$A$3)*标准数据!$B$3+COUNTIF(L45:AP45,标准数据!$A$4)*标准数据!$B$4 -> 0
A46: 寡核苷酸厂房1CNC区域 | B46: 助工 | C46: 杨瑞翔 | D46: ALS13789 | E46: 45700 | F46: =(K46+G46+H46+I46-J46) -> 0 | G46: =SUMIF(积分汇总!$B:$B,,积分汇总!$E:$E) -> 0 | H46: =SUMIF(记录巡查问题条数汇总!$B:$B,,记录巡查问题条数汇总!$E:$E) -> 0 | J46: =SUMIF(安全质量事故!$B:$B,,安全质量事故!$G:$G) -> 0 | K46: =COUNTIF(L46:AP46,标准数据!$A$2)*标准数据!$B$2+COUNTIF(L46:AP46,标准数据!$A$3)*标准数据!$B$3+COUNTIF(L46:AP46,标准数据!$A$4)*标准数据!$B$4 -> 0
A47: 寡核苷酸厂房1CNC区域 | B47: 助工 | C47: 张昊成 | D47: ALS13784 | E47: 45700 | F47: =(K47+G47+H47+I47-J47) -> 0 | G47: =SUMIF(积分汇总!$B:$B,C46,积分汇总!$E:$E) -> 0 | H47: =SUMIF(记录巡查问题条数汇总!$B:$B,C46,记录巡查问题条数汇总!$E:$E) -> 0 | J47: =SUMIF(安全质量事故!$B:$B,C46,安全质量事故!$G:$G) -> 0 | K47: =COUNTIF(L47:AP47,标准数据!$A$2)*标准数据!$B$2+COUNTIF(L47:AP47,标准数据!$A$3)*标准数据!$B$3+COUNTIF(L47:AP47,标准数据!$A$4)*标准数据!$B$4 -> 0
A48: 寡核苷酸厂房1CNC区域 | B48: 助工 | C48: 王思衡 | D48: ALS13785 | E48: 45700 | F48: =(K48+G48+H48+I48-J48) -> 0 | G48: =SUMIF(积分汇总!$B:$B,C47,积分汇总!$E:$E) -> 0 | H48: =SUMIF(记录巡查问题条数汇总!$B:$B,C47,记录巡查问题条数汇总!$E:$E) -> 0 | J48: =SUMIF(安全质量事故!$B:$B,C47,安全质量事故!$G:$G) -> 0 | K48: =COUNTIF(L48:AP48,标准数据!$A$2)*标准数据!$B$2+COUNTIF(L48:AP48,标准数据!$A$3)*标准数据!$B$3+COUNTIF(L48:AP48,标准数据!$A$4)*标准数据!$B$4 -> 0
A49: 寡核苷酸厂房1CNC区域 | B49: 助工 | C49: 张秣骐 | D49: ALS13786 | E49: 45700 | F49: =(K49+G49+H49+I49-J49) -> 0 | G49: =SUMIF(积分汇总!$B:$B,C48,积分汇总!$E:$E) -> 0 | H49: =SUMIF(记录巡查问题条数汇总!$B:$B,C48,记录巡查问题条数汇总!$E:$E) -> 0 | J49: =SUMIF(安全质量事故!$B:$B,C48,安全质量事故!$G:$G) -> 0 | K49: =COUNTIF(L49:AP49,标准数据!$A$2)*标准数据!$B$2+COUNTIF(L49:AP49,标准数据!$A$3)*标准数据!$B$3+COUNTIF(L49:AP49,标准数据!$A$4)*标准数据!$B$4 -> 0
A50: 寡核苷酸厂房1CNC区域 | B50: 助工 | C50: 宋春宏 | D50: ALS13931 | E50: 45770 | F50: =(K50+G50+H50+I50-J50) -> 0 | G50: =SUMIF(积分汇总!$B:$B,C49,积分汇总!$E:$E) -> 0 | H50: =SUMIF(记录巡查问题条数汇总!$B:$B,C49,记录巡查问题条数汇总!$E:$E) -> 0 | J50: =SUMIF(安全质量事故!$B:$B,C49,安全质量事故!$G:$G) -> 0 | K50: =COUNTIF(L50:AP50,标准数据!$A$2)*标准数据!$B$2+COUNTIF(L50:AP50,标准数据!$A$3)*标准数据!$B$3+COUNTIF(L50:AP50,标准数据!$A$4)*标准数据!$B$4 -> 0
A51: 寡核苷酸厂房1CNC区域 | B51: 助工 | C51: 尉勇 | D51: LFX577 | E51: 44389 | F51: =(K51+G51+H51+I51-J51) -> 0 | G51: =SUMIF(积分汇总!$B:$B,C50,积分汇总!$E:$E) -> 0 | H51: =SUMIF(记录巡查问题条数汇总!$B:$B,C50,记录巡查问题条数汇总!$E:$E) -> 0 | J51: =SUMIF(安全质量事故!$B:$B,C50,安全质量事故!$G:$G) -> 0 | K51: =COUNTIF(L51:AP51,标准数据!$A$2)*标准数据!$B$2+COUNTIF(L51:AP51,标准数据!$A$3)*标准数据!$B$3+COUNTIF(L51:AP51,标准数据!$A$4)*标准数据!$B$4 -> 0
A52: 寡核苷酸厂房1CNC区域 | B52: 助工 | C52: 金士新 | D52: LFX859 | E52: 44753 | F52: =(K52+G52+H52+I52-J52) -> 0 | G52: =SUMIF(积分汇总!$B:$B,,积分汇总!$E:$E) -> 0 | H52: =SUMIF(记录巡查问题条数汇总!$B:$B,,记录巡查问题条数汇总!$E:$E) -> 0 | J52: =SUMIF(安全质量事故!$B:$B,,安全质量事故!$G:$G) -> 0 | K52: =COUNTIF(L52:AP52,标准数据!$A$2)*标准数据!$B$2+COUNTIF(L52:AP52,标准数据!$A$3)*标准数据!$B$3+COUNTIF(L52:AP52,标准数据!$A$4)*标准数据!$B$4 -> 0
A53: 寡核苷酸厂房1CNC区域 | B53: 助工 | C53: 吕云亮 | D53: ALS14026 | E53: 45791 | F53: =(K53+G53+H53+I53-J53) -> 0 | G53: =SUMIF(积分汇总!$B:$B,C52,积分汇总!$E:$E) -> 0 | H53: =SUMIF(记录巡查问题条数汇总!$B:$B,C52,记录巡查问题条数汇总!$E:$E) -> 0 | J53: =SUMIF(安全质量事故!$B:$B,C52,安全质量事故!$G:$G) -> 0 | K53: =COUNTIF(L53:AP53,标准数据!$A$2)*标准数据!$B$2+COUNTIF(L53:AP53,标准数据!$A$3)*标准数据!$B$3+COUNTIF(L53:AP53,标准数据!$A$4)*标准数据!$B$4 -> 0
A54: 寡核苷酸厂房1CNC区域 | B54: 助工 | C54: 鲁斌 | D54: ALS14129 | E54: 45819 | F54: =(K54+G54+H54+I54-J54) -> 0 | G54: =SUMIF(积分汇总!$B:$B,C53,积分汇总!$E:$E) -> 0 | H54: =SUMIF(记录巡查问题条数汇总!$B:$B,C53,记录巡查问题条数汇总!$E:$E) -> 0 | J54: =SUMIF(安全质量事故!$B:$B,C53,安全质量事故!$G:$G) -> 0 | K54: =COUNTIF(L54:AP54,标准数据!$A$2)*标准数据!$B$2+COUNTIF(L54:AP54,标准数据!$A$3)*标准数据!$B$3+COUNTIF(L54:AP54,标准数据!$A$4)*标准数据!$B$4 -> 0
A55: 寡核苷酸厂房1CNC区域 | B55: 助工 | C55: 郭淼 | D55: ALS14154 | E55: 45826 | F55: =(K55+G55+H55+I55-J55) -> 0 | G55: =SUMIF(积分汇总!$B:$B,,积分汇总!$E:$E) -> 0 | H55: =SUMIF(记录巡查问题条数汇总!$B:$B,,记录巡查问题条数汇总!$E:$E) -> 0 | J55: =SUMIF(安全质量事故!$B:$B,,安全质量事故!$G:$G) -> 0 | K55: =COUNTIF(L55:AP55,标准数据!$A$2)*标准数据!$B$2+COUNTIF(L55:AP55,标准数据!$A$3)*标准数据!$B$3+COUNTIF(L55:AP55,标准数据!$A$4)*标准数据!$B$4 -> 0
A56: 寡核苷酸厂房1CNC区域 | B56: 助工 | C56: 贾同才 | D56: ALS14236 | E56: 45840 | F56: =(K56+G56+H56+I56-J56) -> 0 | G56: =SUMIF(积分汇总!$B:$B,C55,积分汇总!$E:$E) -> 0 | H56: =SUMIF(记录巡查问题条数汇总!$B:$B,C55,记录巡查问题条数汇总!$E:$E) -> 0 | J56: =SUMIF(安全质量事故!$B:$B,C55,安全质量事故!$G:$G) -> 0 | K56: =COUNTIF(L56:AP56,标准数据!$A$2)*标准数据!$B$2+COUNTIF(L56:AP56,标准数据!$A$3)*标准数据!$B$3+COUNTIF(L56:AP56,标准数据!$A$4)*标准数据!$B$4 -> 0
A57: 寡核苷酸厂房1CNC区域 | B57: 助工 | C57: 熊俊伟 | D57: ALS14632 | E57: 45882 | F57: =(K57+G57+H57+I57-J57) -> 0 | G57: =SUMIF(积分汇总!$B:$B,C56,积分汇总!$E:$E) -> 0 | H57: =SUMIF(记录巡查问题条数汇总!$B:$B,C56,记录巡查问题条数汇总!$E:$E) -> 0 | J57: =SUMIF(安全质量事故!$B:$B,C56,安全质量事故!$G:$G) -> 0 | K57: =COUNTIF(L57:AP57,标准数据!$A$2)*标准数据!$B$2+COUNTIF(L57:AP57,标准数据!$A$3)*标准数据!$B$3+COUNTIF(L57:AP57,标准数据!$A$4)*标准数据!$B$4 -> 0
A58: 寡核苷酸厂房1CNC区域 | B58: 助工 | C58: 田芸龙 | D58: ALS14573 | E58: 45875 | F58: =(K58+G58+H58+I58-J58) -> 0 | G58: =SUMIF(积分汇总!$B:$B,C57,积分汇总!$E:$E) -> 0 | H58: =SUMIF(记录巡查问题条数汇总!$B:$B,C57,记录巡查问题条数汇总!$E:$E) -> 0 | J58: =SUMIF(安全质量事故!$B:$B,C57,安全质量事故!$G:$G) -> 0 | K58: =COUNTIF(L58:AP58,标准数据!$A$2)*标准数据!$B$2+COUNTIF(L58:AP58,标准数据!$A$3)*标准数据!$B$3+COUNTIF(L58:AP58,标准数据!$A$4)*标准数据!$B$4 -> 0
A59: 寡核苷酸厂房1CNC区域 | B59: 助工 | C59: 李塨榮 | D59: ALS14574 | E59: 45875 | F59: =(K59+G59+H59+I59-J59) -> 0 | G59: =SUMIF(积分汇总!$B:$B,C58,积分汇总!$E:$E) -> 0 | H59: =SUMIF(记录巡查问题条数汇总!$B:$B,C58,记录巡查问题条数汇总!$E:$E) -> 0 | J59: =SUMIF(安全质量事故!$B:$B,C58,安全质量事故!$G:$G) -> 0 | K59: =COUNTIF(L59:AP59,标准数据!$A$2)*标准数据!$B$2+COUNTIF(L59:AP59,标准数据!$A$3)*标准数据!$B$3+COUNTIF(L59:AP59,标准数据!$A$4)*标准数据!$B$4 -> 0
A60: 寡核苷酸厂房1CNC区域 | B60: 助工 | C60: 王爱港 | D60: AMM4102 | E60: 45392 | F60: =(K60+G60+H60+I60-J60) -> 0 | G60: =SUMIF(积分汇总!$B:$B,C59,积分汇总!$E:$E) -> 0 | H60: =SUMIF(记录巡查问题条数汇总!$B:$B,C59,记录巡查问题条数汇总!$E:$E) -> 0 | J60: =SUMIF(安全质量事故!$B:$B,C59,安全质量事故!$G:$G) -> 0 | K60: =COUNTIF(L60:AP60,标准数据!$A$2)*标准数据!$B$2+COUNTIF(L60:AP60,标准数据!$A$3)*标准数据!$B$3+COUNTIF(L60:AP60,标准数据!$A$4)*标准数据!$B$4 -> 0
A61: 寡核苷酸厂房1CNC区域 | B61: 助工 | C61: 王俊淋 | D61: ALS14610 | E61: 45889 | F61: =(K61+G61+H61+I61-J61) -> 0 | G61: =SUMIF(积分汇总!$B:$B,C60,积分汇总!$E:$E) -> 0 | H61: =SUMIF(记录巡查问题条数汇总!$B:$B,C60,记录巡查问题条数汇总!$E:$E) -> 0 | J61: =SUMIF(安全质量事故!$B:$B,C60,安全质量事故!$G:$G) -> 0 | K61: =COUNTIF(L61:AP61,标准数据!$A$2)*标准数据!$B$2+COUNTIF(L61:AP61,标准数据!$A$3)*标准数据!$B$3+COUNTIF(L61:AP61,标准数据!$A$4)*标准数据!$B$4 -> 0
A62: 寡核苷酸厂房1CNC区域 | B62: 助工 | C62: 陆明 | D62: ALS15138 | E62: 45959 | F62: =(K62+G62+H62+I62-J62) -> 0 | G62: =SUMIF(积分汇总!$B:$B,C61,积分汇总!$E:$E) -> 0 | H62: =SUMIF(记录巡查问题条数汇总!$B:$B,C61,记录巡查问题条数汇总!$E:$E) -> 0 | J62: =SUMIF(安全质量事故!$B:$B,C61,安全质量事故!$G:$G) -> 0 | K62: =COUNTIF(L62:AP62,标准数据!$A$2)*标准数据!$B$2+COUNTIF(L62:AP62,标准数据!$A$3)*标准数据!$B$3+COUNTIF(L62:AP62,标准数据!$A$4)*标准数据!$B$4 -> 0
...

Sheet Sheet1
A2: DCS | B2: DCS&仪表组 | C2: 工程师 | D2: 常宝轩 | E2: ALS15601 | F2: 46001
A3: DCS | B3: DCS&仪表组 | C3: 工程师 | D3: 李天亮 | E3: ALS16323 | F3: 46120
A4: DCS | B4: DCS&仪表组 | C4: 工程师 | D4: 周铎 | E4: ALS17058 | F4: 46188
A5: DCS | B5: DCS&仪表组 | C5: 工程师 | D5: 宋泽华 | E5: ALS18172 | F5: 46232
A6: DCS | B6: DCS&仪表组 | C6: 经理 | D6: 王腾蛟 | E6: ALS10164 | F6: 44755
A7: DCS | B7: DCS&仪表组 | C7: 助工 | D7: 赵威 | E7: ALS10177 | F7: 44755
A8: DCS | B8: DCS&仪表组 | C8: 助工 | D8: 巩天龙 | E8: ALS14056 | F8: 45798
A9: DCS | B9: DCS&仪表组 | C9: 助工 | D9: 刘百威 | E9: ALS17140 | F9: 46183
A10: DCS | B10: DCS&仪表组 | C10: 助工 | D10: 刘占彪 | E10: ALS17596 | F10: 46197
A11: DCS | B11: DCS&仪表组 | C11: 助工 | D11: 徐湘育 | E11: ALS17621 | F11: 46197
A12: DCS | B12: DCS&仪表组 | C12: 操作工 | D12: 王哲 | E12: ALS16276 | F12: 46113
A13: DCS | B13: DCS&仪表组 | C13: 操作工 | D13: 许泓浩 | E13: ALS13365 | F13: 45532
... A288: 11号楼CNC车间 | B288: 多肽厂房2CNC区域 | C288: 操作工 | D288: 马勇 | E288: LFX079 | F288: 43333
A289: 11号楼CNC车间 | B289: 多肽厂房2CNC区域 | C289: 操作工 | D289: 赵忠波 | E289: AMM4428 | F289: 0901调任
A290: 11号楼D级车间 | B290: 多肽厂房2CNC区域 | C290: 助工 | D290: 李泉 | E290: ALS14766 | F290: 45901
A291: 12号楼 | B291: 多肽厂房2CNC区域 | C291: 工程师 | D291: 王朝阳 | E291: ALS4568 | F291: 43299
A292: 12号楼 | B292: 多肽厂房2CNC区域 | C292: 班长 | D292: 黄宣童 | E292: ALS14566 | F292: 45875
A293: 12号楼 | B293: 多肽厂房2CNC区域 | C293: 班长 | D293: 杜少游 | E293: AMM0587 | F293: 44018
A294: 12号楼 | B294: 多肽厂房2CNC区域 | C294: 班长 | D294: 陶子明 | E294: AMM3993 | F294: 41340
A295: 12号楼 | B295: 多肽厂房2CNC区域 | C295: 班长 | D295: 李强 | E295: ALS15386 | F295: 45980
A296: 12号楼 | B296: 多肽厂房2CNC区域 | C296: 助工 | D296: 刘鸿伟 | E296: ALS14671 | F296: 45889
A297: 12号楼 | B297: 多肽厂房2CNC区域 | C297: 助工 | D297: 于洋 | E297: LFX855 | F297: 44753
A298: 12号楼 | B298: 多肽厂房2CNC区域 | C298: 助工 | D298: 姚宏昌 | E298: ADH5609 | F298: 45139
A299: 12号楼 | B299: 多肽厂房2CNC区域 | C299: 助工 | D299: 杨文军 | E299: AMM2310 | F299: 0901调任
A300: 12号楼 | B300: 多肽厂房2CNC区域 | C300: 助工 | D300: 倪道鑫 | E300: AMM2965 | F300: 0901调任
A301: 12号楼 | B301: 多肽厂房2CNC区域 | C301: 助工 | D301: 李玉刚 | E301: ALS13121 | F301: 45483
A302: 12号楼 | B302: 多肽厂房2CNC区域 | C302: 助工 | D302: 张艾驰 | E302: ALS14672 | F302: 45889
A303: 12号楼 | B303: 多肽厂房2CNC区域 | C303: 助工 | D303: 张彦彬 | E303: ALS14730 | F303: 45896
A304: 12号楼 | B304: 多肽厂房2CNC区域 | C304: 助工 | D304: 柳浩然 | E304: ADH6302 | F304: 45509
A305: 12号楼 | B305: 多肽厂房2CNC区域 | C305: 助工 | D305: 周智升 | E305: ALS15128 | F305: 45959
A306: 12号楼 | B306: 多肽厂房2CNC区域 | C306: 助工 | D306: 康楷睿 | E306: ALS15555 | F306: 45994
A307: 12号楼 | B307: 多肽厂房2CNC区域 | C307: 助工 | D307: 张文豪 | E307: ALS14704 | F307: 45896
A308: 12号楼 | B308: 多肽厂房2CNC区域 | C308: 助工 | D308: 王鑫（ALS14706） | E308: ALS14706 | F308: 45896
A309: 12号楼 | B309: 多肽厂房2CNC区域 | C309: 助工 | D309: 李落羽 | E309: ALS15554 | F309: 45994
A310: 12号楼 | B310: 多肽厂房2CNC区域 | C310: 助工 | D310: 李宇琛 | E310: ALS15647 | F310: 46001
A311: 12号楼 | B311: 多肽厂房2CNC区域 | C311: 助工 | D311: 王超 | E311: ALS15696 | F311: 46008
A312: 12号楼 | B312: 多肽厂房2CNC区域 | C312: 助工 | D312: 权靖喆 | E312: ALS15471 | F312: 45987
... A388: 12号楼 | B388: 多肽厂房2CNC区域 | C388: 操作工 | D388: 尹博 | E388: BDH0550 | F388: 44463
A389: 12号楼 | B389: 多肽厂房2CNC区域 | C389: 操作工 | D389: 丁方辉 | E389: AMM4084 | F389: 0901调任
A390: 12号楼 | B390: 多肽厂房2CNC区域 | C390: 操作工 | D390: 马孟春 | E390: ALS14738 | F390: 45896
...

Sheet 复核人
A1: 4#楼1&2车间：田志勇 | B1: 刘其琛
A2: 4#楼3&4车间： 刘磊
A3: 4号楼制备组：皮轶杰
A4: 11#楼CNC车间：门学友 | B4: 杜永宝
A5: 11#楼D级区：梁光强/李晓刚
A6: 5号楼：冯恩利 | B6: 魏鹏
A7: 12号楼：代海鑫 | B7: 李延龙
A8: 验证组 / DCS / 电子设备维护 / 合规&培训 ： 刘亚南 | B8: 刘亚南
A9: 环保设备设施 ：刘文龙 | B9: 刘文龙
A10: 外围/罐区/泵房：赵艳春/吴宗璇
A11: 清洗组： 陈正兴
A12: 安全组 | B12: 李国清
A13: 生产技术转移组（辅料&毒素连接体） | B13: 刘其琛
A14: 生产技术转移组（多肽） | B14: 蔡森
A15: 13号楼 | B15: 李子凯

Sheet 一线人员 (2)
G1: =SUM(G4:G1467) -> 0
A2: 车间 | C2: 职务 | D2: 姓名 | E2: 员工编号 | F2: 入职日期 | G2: 实际奖金合计 | H2: 日常巡查扣款 | I2: 记录巡查扣款 | J2: 定点摄影最佳区域和最差区域评比 | K2: 安全事故扣款 | L2: 5S日检奖金合计 | M2: 09月 | AS2: 4#楼1&2车间“a、b、c”分布情况
M3: 46266 | N3: 46267 | O3: 46268 | P3: 46269 | Q3: 46270 | R3: 46271 | S3: 46272 | T3: 46273 | U3: 46274 | V3: 46275 | W3: 46276 | X3: 46277 | Y3: 46278 | Z3: 46279 | AA3: 46280 | AB3: 46281 | AC3: 46282 | AD3: 46283 | AE3: 46284 | AF3: 46285 | AG3: 46286 | AH3: 46287 | AI3: 46288 | AJ3: 46289 | AK3: 46290 | AL3: 46291 | AM3: 46292 | AN3: 46293 | AO3: 46294 | AP3: 46295 | AQ3: 46296 | AR3: 备注 | AS3: “a”占比 | AT3: “b”占比 | AU3: “c”占比 | AV3: 核对1 | AW3: 核对2
A4: 4号楼1&2车间 | B4: 寡核苷酸厂房1D级区域 | C4: 工程师 | D4: 王宇亭 | E4: ALS14235 | F4: 45840 | G4: =(L4+H4+I4+J4-K4) -> 0 | H4: =SUMIF(积分汇总!$B:$B,D187,积分汇总!$E:$E) -> 0 | I4: =SUMIF(记录巡查问题条数汇总!$B:$B,D187,记录巡查问题条数汇总!$E:$E) -> 0 | K4: =SUMIF(安全质量事故!$B:$B,D187,安全质量事故!$G:$G) -> 0 | L4: =COUNTIF(M4:AQ4,标准数据!$A$2)*标准数据!$B$2+COUNTIF(M4:AQ4,标准数据!$A$3)*标准数据!$B$3+COUNTIF(M4:AQ4,标准数据!$A$4)*标准数据!$B$4 -> 0 | AR4: =VLOOKUP(E4,'[2]离职人员&调出人员'!$C:$C,1,0) -> #N/A | AS4: =COUNTIF($M$4:$AQ$92,"a") -> 0 | AT4: =COUNTIF($M$4:$AQ$92,"b") -> 0 | AU4: =COUNTIF($M$4:$AQ$92,"c") -> 0 | AV4: =VLOOKUP(E4,[1]生产部!$C:$I,7,0) -> 班组 | AW4: =VLOOKUP(E4,[1]生产部!$C:$I,6,0) -> 4号楼1&2车间
A5: 4号楼1&2车间 | B5: 寡核苷酸厂房1D级区域 | C5: 工程师 | D5: 张政 | E5: ALS15334 | F5: 45980 | G5: =(L5+H5+I5+J5-K5) -> 0 | H5: =SUMIF(积分汇总!$B:$B,D4,积分汇总!$E:$E) -> 0 | I5: =SUMIF(记录巡查问题条数汇总!$B:$B,D4,记录巡查问题条数汇总!$E:$E) -> 0 | K5: =SUMIF(安全质量事故!$B:$B,D4,安全质量事故!$G:$G) -> 0 | L5: =COUNTIF(M5:AQ5,标准数据!$A$2)*标准数据!$B$2+COUNTIF(M5:AQ5,标准数据!$A$3)*标准数据!$B$3+COUNTIF(M5:AQ5,标准数据!$A$4)*标准数据!$B$4 -> 0 | AS5: =AS4/($AS$4+$AT$4+$AU$4) -> #DIV/0! | AT5: =AT4/($AS$4+$AT$4+$AU$4) -> #DIV/0! | AU5: =AU4/($AS$4+$AT$4+$AU$4) -> #DIV/0! | AV5: =VLOOKUP(E5,[1]生产部!$C:$I,7,0) -> 项目组 | AW5: =VLOOKUP(E5,[1]生产部!$C:$I,6,0) -> 4号楼1&2车间
A6: 4号楼1&2车间 | B6: 寡核苷酸厂房1D级区域 | C6: 工程师 | D6: 杨晨 | E6: ALS15954 | F6: 46050 | G6: =(L6+H6+I6+J6-K6) -> 0 | H6: =SUMIF(积分汇总!$B:$B,D5,积分汇总!$E:$E) -> 0 | I6: =SUMIF(记录巡查问题条数汇总!$B:$B,D5,记录巡查问题条数汇总!$E:$E) -> 0 | K6: =SUMIF(安全质量事故!$B:$B,D5,安全质量事故!$G:$G) -> 0 | L6: =COUNTIF(M6:AQ6,标准数据!$A$2)*标准数据!$B$2+COUNTIF(M6:AQ6,标准数据!$A$3)*标准数据!$B$3+COUNTIF(M6:AQ6,标准数据!$A$4)*标准数据!$B$4 -> 0 | AV6: =VLOOKUP(E6,[1]生产部!$C:$I,7,0) -> 常白 | AW6: =VLOOKUP(E6,[1]生产部!$C:$I,6,0) -> 4号楼1&2车间
A7: 4号楼1&2车间 | B7: 寡核苷酸厂房1D级区域 | C7: 工程师 | D7: 邵英强 | E7: ALS16808 | F7: 46153 | G7: =(L7+H7+I7+J7-K7) -> 0 | H7: =SUMIF(积分汇总!$B:$B,D6,积分汇总!$E:$E) -> 0 | I7: =SUMIF(记录巡查问题条数汇总!$B:$B,D6,记录巡查问题条数汇总!$E:$E) -> 0 | K7: =SUMIF(安全质量事故!$B:$B,D6,安全质量事故!$G:$G) -> 0 | L7: =COUNTIF(M7:AQ7,标准数据!$A$2)*标准数据!$B$2+COUNTIF(M7:AQ7,标准数据!$A$3)*标准数据!$B$3+COUNTIF(M7:AQ7,标准数据!$A$4)*标准数据!$B$4 -> 0 | AV7: =VLOOKUP(E7,[1]生产部!$C:$I,7,0) -> 项目组 | AW7: =VLOOKUP(E7,[1]生产部!$C:$I,6,0) -> 4号楼1&2车间
A8: 4号楼1&2车间 | B8: 寡核苷酸厂房1D级区域 | C8: 工程师 | D8: 郑昊 | E8: ALS11847 | F8: 45019 | G8: =(L8+H8+I8+J8-K8) -> 0 | H8: =SUMIF(积分汇总!$B:$B,D7,积分汇总!$E:$E) -> 0 | I8: =SUMIF(记录巡查问题条数汇总!$B:$B,D7,记录巡查问题条数汇总!$E:$E) -> 0 | K8: =SUMIF(安全质量事故!$B:$B,D7,安全质量事故!$G:$G) -> 0 | L8: =COUNTIF(M8:AQ8,标准数据!$A$2)*标准数据!$B$2+COUNTIF(M8:AQ8,标准数据!$A$3)*标准数据!$B$3+COUNTIF(M8:AQ8,标准数据!$A$4)*标准数据!$B$4 -> 0 | AV8: =VLOOKUP(E8,[1]生产部!$C:$I,7,0) -> 项目组 | AW8: =VLOOKUP(E8,[1]生产部!$C:$I,6,0) -> 4号楼1&2车间
A9: 4号楼1&2车间 | B9: 寡核苷酸厂房1D级区域 | C9: 工程师 | D9: 宋懂林 | E9: ALS17329 | F9: 46208 | G9: =(L9+H9+I9+J9-K9) -> 0 | H9: =SUMIF(积分汇总!$B:$B,D8,积分汇总!$E:$E) -> 0 | I9: =SUMIF(记录巡查问题条数汇总!$B:$B,D8,记录巡查问题条数汇总!$E:$E) -> 0 | K9: =SUMIF(安全质量事故!$B:$B,D8,安全质量事故!$G:$G) -> 0 | L9: =COUNTIF(M9:AQ9,标准数据!$A$2)*标准数据!$B$2+COUNTIF(M9:AQ9,标准数据!$A$3)*标准数据!$B$3+COUNTIF(M9:AQ9,标准数据!$A$4)*标准数据!$B$4 -> 0 | AV9: =VLOOKUP(E9,[1]生产部!$C:$I,7,0) -> 常白 | AW9: =VLOOKUP(E9,[1]生产部!$C:$I,6,0) -> 4号楼1&2车间
A10: 4号楼1&2车间 | B10: 寡核苷酸厂房1D级区域 | C10: 工程师 | D10: 张剑 | E10: ALS17336 | F10: 46215 | G10: =(L10+H10+I10+J10-K10) -> 0 | H10: =SUMIF(积分汇总!$B:$B,D9,积分汇总!$E:$E) -> 0 | I10: =SUMIF(记录巡查问题条数汇总!$B:$B,D9,记录巡查问题条数汇总!$E:$E) -> 0 | K10: =SUMIF(安全质量事故!$B:$B,D9,安全质量事故!$G:$G) -> 0 | L10: =COUNTIF(M10:AQ10,标准数据!$A$2)*标准数据!$B$2+COUNTIF(M10:AQ10,标准数据!$A$3)*标准数据!$B$3+COUNTIF(M10:AQ10,标准数据!$A$4)*标准数据!$B$4 -> 0 | AV10: =VLOOKUP(E10,[1]生产部!$C:$I,7,0) -> 常白 | AW10: =VLOOKUP(E10,[1]生产部!$C:$I,6,0) -> 4号楼1&2车间
A11: 4号楼1&2车间 | B11: 寡核苷酸厂房1D级区域 | C11: 工程师 | D11: 王淼 | E11: ALS17335 | F11: 46215 | G11: =(L11+H11+I11+J11-K11) -> 0 | H11: =SUMIF(积分汇总!$B:$B,D8,积分汇总!$E:$E) -> 0 | I11: =SUMIF(记录巡查问题条数汇总!$B:$B,D8,记录巡查问题条数汇总!$E:$E) -> 0 | K11: =SUMIF(安全质量事故!$B:$B,D8,安全质量事故!$G:$G) -> 0 | L11: =COUNTIF(M11:AQ11,标准数据!$A$2)*标准数据!$B$2+COUNTIF(M11:AQ11,标准数据!$A$3)*标准数据!$B$3+COUNTIF(M11:AQ11,标准数据!$A$4)*标准数据!$B$4 -> 0 | AV11: =VLOOKUP(E11,[1]生产部!$C:$I,7,0) -> 常白 | AW11: =VLOOKUP(E11,[1]生产部!$C:$I,6,0) -> 4号楼1&2车间
A12: 4号楼1&2车间 | B12: 寡核苷酸厂房1D级区域 | C12: 工程师 | D12: 赵智博 | E12: ALS17337 | F12: 46215 | G12: =(L12+H12+I12+J12-K12) -> 0 | H12: =SUMIF(积分汇总!$B:$B,D11,积分汇总!$E:$E) -> 0 | I12: =SUMIF(记录巡查问题条数汇总!$B:$B,D11,记录巡查问题条数汇总!$E:$E) -> 0 | K12: =SUMIF(安全质量事故!$B:$B,D11,安全质量事故!$G:$G) -> 0 | L12: =COUNTIF(M12:AQ12,标准数据!$A$2)*标准数据!$B$2+COUNTIF(M12:AQ12,标准数据!$A$3)*标准数据!$B$3+COUNTIF(M12:AQ12,标准数据!$A$4)*标准数据!$B$4 -> 0 | AV12: =VLOOKUP(E12,[1]生产部!$C:$I,7,0) -> 常白 | AW12: =VLOOKUP(E12,[1]生产部!$C:$I,6,0) -> 4号楼1&2车间
A13: 4号楼1&2车间 | B13: 寡核苷酸厂房1D级区域 | C13: 工程师 | D13: 张兴海 | E13: ALS12958 | F13: 45448 | G13: =(L13+H13+I13+J13-K13) -> 0 | H13: =SUMIF(积分汇总!$B:$B,D10,积分汇总!$E:$E) -> 0 | I13: =SUMIF(记录巡查问题条数汇总!$B:$B,D10,记录巡查问题条数汇总!$E:$E) -> 0 | K13: =SUMIF(安全质量事故!$B:$B,D10,安全质量事故!$G:$G) -> 0 | L13: =COUNTIF(M13:AQ13,标准数据!$A$2)*标准数据!$B$2+COUNTIF(M13:AQ13,标准数据!$A$3)*标准数据!$B$3+COUNTIF(M13:AQ13,标准数据!$A$4)*标准数据!$B$4 -> 0 | AV13: =VLOOKUP(E13,[1]生产部!$C:$I,7,0) -> 班组 | AW13: =VLOOKUP(E13,[1]生产部!$C:$I,6,0) -> 4号楼1&2车间
A14: 4号楼1&2车间 | B14: 寡核苷酸厂房1D级区域 | C14: 工程师 | D14: 刘太安 | E14: FX2743 | F14: 43237 | G14: =(L14+H14+I14+J14-K14) -> 0 | H14: =SUMIF(积分汇总!$B:$B,D13,积分汇总!$E:$E) -> 0 | I14: =SUMIF(记录巡查问题条数汇总!$B:$B,D13,记录巡查问题条数汇总!$E:$E) -> 0 | K14: =SUMIF(安全质量事故!$B:$B,D13,安全质量事故!$G:$G) -> 0 | L14: =COUNTIF(M14:AQ14,标准数据!$A$2)*标准数据!$B$2+COUNTIF(M14:AQ14,标准数据!$A$3)*标准数据!$B$3+COUNTIF(M14:AQ14,标准数据!$A$4)*标准数据!$B$4 -> 0 | AV14: =VLOOKUP(E14,[1]生产部!$C:$I,7,0) -> 项目组 | AW14: =VLOOKUP(E14,[1]生产部!$C:$I,6,0) -> 4号楼1&2车间
A15: 4号楼1&2车间 | B15: 寡核苷酸厂房1D级区域 | C15: 班长 | D15: 苏谊 | E15: BDH0640 | F15: 44732 | G15: =(L15+H15+I15+J15-K15) -> 0 | H15: =SUMIF(积分汇总!$B:$B,D14,积分汇总!$E:$E) -> 0 | I15: =SUMIF(记录巡查问题条数汇总!$B:$B,D14,记录巡查问题条数汇总!$E:$E) -> 0 | K15: =SUMIF(安全质量事故!$B:$B,D14,安全质量事故!$G:$G) -> 0 | L15: =COUNTIF(M15:AQ15,标准数据!$A$2)*标准数据!$B$2+COUNTIF(M15:AQ15,标准数据!$A$3)*标准数据!$B$3+COUNTIF(M15:AQ15,标准数据!$A$4)*标准数据!$B$4 -> 0 | AV15: =VLOOKUP(E15,[1]生产部!$C:$I,7,0) -> 班组 | AW15: =VLOOKUP(E15,[1]生产部!$C:$I,6,0) -> 4号楼1&2车间
A16: 4号楼1&2车间 | B16: 寡核苷酸厂房1D级区域 | C16: 班长 | D16: 周玉凯 | E16: ALS11232 | F16: 44774 | G16: =(L16+H16+I16+J16-K16) -> 0 | H16: =SUMIF(积分汇总!$B:$B,D16,积分汇总!$E:$E) -> 0 | I16: =SUMIF(记录巡查问题条数汇总!$B:$B,D16,记录巡查问题条数汇总!$E:$E) -> 0 | K16: =SUMIF(安全质量事故!$B:$B,D16,安全质量事故!$G:$G) -> 0 | L16: =COUNTIF(M16:AQ16,标准数据!$A$2)*标准数据!$B$2+COUNTIF(M16:AQ16,标准数据!$A$3)*标准数据!$B$3+COUNTIF(M16:AQ16,标准数据!$A$4)*标准数据!$B$4 -> 0 | AV16: =VLOOKUP(E16,[1]生产部!$C:$I,7,0) -> 班组 | AW16: =VLOOKUP(E16,[1]生产部!$C:$I,6,0) -> 4号楼1&2车间
A17: 4号楼1&2车间 | B17: 寡核苷酸厂房1D级区域 | C17: 助工 | D17: 刘栋 | E17: ALS11215 | F17: 44774 | G17: =(L17+H17+I17+J17-K17) -> 0 | H17: =SUMIF(积分汇总!$B:$B,D16,积分汇总!$E:$E) -> 0 | I17: =SUMIF(记录巡查问题条数汇总!$B:$B,D16,记录巡查问题条数汇总!$E:$E) -> 0 | K17: =SUMIF(安全质量事故!$B:$B,D16,安全质量事故!$G:$G) -> 0 | L17: =COUNTIF(M17:AQ17,标准数据!$A$2)*标准数据!$B$2+COUNTIF(M17:AQ17,标准数据!$A$3)*标准数据!$B$3+COUNTIF(M17:AQ17,标准数据!$A$4)*标准数据!$B$4 -> 0 | AV17: =VLOOKUP(E17,[1]生产部!$C:$I,7,0) -> 项目组倒班 | AW17: =VLOOKUP(E17,[1]生产部!$C:$I,6,0) -> 4号楼1&2车间
A18: 4号楼1&2车间 | B18: 寡核苷酸厂房1D级区域 | C18: 助工 | D18: 张昊（ALS11789） | E18: ALS11789 | F18: 44998 | G18: =(L18+H18+I18+J18-K18) -> 0 | H18: =SUMIF(积分汇总!$B:$B,D17,积分汇总!$E:$E) -> 0 | I18: =SUMIF(记录巡查问题条数汇总!$B:$B,D17,记录巡查问题条数汇总!$E:$E) -> 0 | K18: =SUMIF(安全质量事故!$B:$B,D17,安全质量事故!$G:$G) -> 0 | L18: =COUNTIF(M18:AQ18,标准数据!$A$2)*标准数据!$B$2+COUNTIF(M18:AQ18,标准数据!$A$3)*标准数据!$B$3+COUNTIF(M18:AQ18,标准数据!$A$4)*标准数据!$B$4 -> 0 | AV18: =VLOOKUP(E18,[1]生产部!$C:$I,7,0) -> 项目组倒班 | AW18: =VLOOKUP(E18,[1]生产部!$C:$I,6,0) -> 4号楼1&2车间
A19: 4号楼1&2车间 | B19: 寡核苷酸厂房1D级区域 | C19: 助工 | D19: 张鹏飞 | E19: ALS11846 | F19: 45019 | G19: =(L19+H19+I19+J19-K19) -> 0 | H19: =SUMIF(积分汇总!$B:$B,D18,积分汇总!$E:$E) -> 0 | I19: =SUMIF(记录巡查问题条数汇总!$B:$B,D18,记录巡查问题条数汇总!$E:$E) -> 0 | K19: =SUMIF(安全质量事故!$B:$B,D18,安全质量事故!$G:$G) -> 0 | L19: =COUNTIF(M19:AQ19,标准数据!$A$2)*标准数据!$B$2+COUNTIF(M19:AQ19,标准数据!$A$3)*标准数据!$B$3+COUNTIF(M19:AQ19,标准数据!$A$4)*标准数据!$B$4 -> 0 | AV19: =VLOOKUP(E19,[1]生产部!$C:$I,7,0) -> 常白 | AW19: =VLOOKUP(E19,[1]生产部!$C:$I,6,0) -> 4号楼1&2车间
A20: 4号楼1&2车间 | B20: 寡核苷酸厂房1D级区域 | C20: 助工 | D20: 范锺铭 | E20: ALS12311 | F20: 45138 | G20: =(L20+H20+I20+J20-K20) -> 0 | H20: =SUMIF(积分汇总!$B:$B,D19,积分汇总!$E:$E) -> 0 | I20: =SUMIF(记录巡查问题条数汇总!$B:$B,D19,记录巡查问题条数汇总!$E:$E) -> 0 | K20: =SUMIF(安全质量事故!$B:$B,D19,安全质量事故!$G:$G) -> 0 | L20: =COUNTIF(M20:AQ20,标准数据!$A$2)*标准数据!$B$2+COUNTIF(M20:AQ20,标准数据!$A$3)*标准数据!$B$3+COUNTIF(M20:AQ20,标准数据!$A$4)*标准数据!$B$4 -> 0 | AV20: =VLOOKUP(E20,[1]生产部!$C:$I,7,0) -> 班组 | AW20: =VLOOKUP(E20,[1]生产部!$C:$I,6,0) -> 4号楼1&2车间
A21: 4号楼1&2车间 | B21: 寡核苷酸厂房1D级区域 | C21: 助工 | D21: 朱永祺 | E21: ALS11786 | F21: 44998 | G21: =(L21+H21+I21+J21-K21) -> 0 | H21: =SUMIF(积分汇总!$B:$B,D20,积分汇总!$E:$E) -> 0 | I21: =SUMIF(记录巡查问题条数汇总!$B:$B,D20,记录巡查问题条数汇总!$E:$E) -> 0 | K21: =SUMIF(安全质量事故!$B:$B,D20,安全质量事故!$G:$G) -> 0 | L21: =COUNTIF(M21:AQ21,标准数据!$A$2)*标准数据!$B$2+COUNTIF(M21:AQ21,标准数据!$A$3)*标准数据!$B$3+COUNTIF(M21:AQ21,标准数据!$A$4)*标准数据!$B$4 -> 0 | AV21: =VLOOKUP(E21,[1]生产部!$C:$I,7,0) -> 常白 | AW21: =VLOOKUP(E21,[1]生产部!$C:$I,6,0) -> 4号楼1&2车间
A22: 4号楼1&2车间 | B22: 寡核苷酸厂房1D级区域 | C22: 助工 | D22: 王城 | E22: ALS12745 | F22: 45231 | G22: =(L22+H22+I22+J22-K22) -> 0 | H22: =SUMIF(积分汇总!$B:$B,D21,积分汇总!$E:$E) -> 0 | I22: =SUMIF(记录巡查问题条数汇总!$B:$B,D21,记录巡查问题条数汇总!$E:$E) -> 0 | K22: =SUMIF(安全质量事故!$B:$B,D21,安全质量事故!$G:$G) -> 0 | L22: =COUNTIF(M22:AQ22,标准数据!$A$2)*标准数据!$B$2+COUNTIF(M22:AQ22,标准数据!$A$3)*标准数据!$B$3+COUNTIF(M22:AQ22,标准数据!$A$4)*标准数据!$B$4 -> 0 | AV22: =VLOOKUP(E22,[1]生产部!$C:$I,7,0) -> 班组 | AW22: =VLOOKUP(E22,[1]生产部!$C:$I,6,0) -> 4号楼1&2车间
A23: 4号楼1&2车间 | B23: 寡核苷酸厂房1D级区域 | C23: 助工 | D23: 施如富 | E23: ALS13069 | F23: 45476 | G23: =(L23+H23+I23+J23-K23) -> 0 | H23: =SUMIF(积分汇总!$B:$B,D22,积分汇总!$E:$E) -> 0 | I23: =SUMIF(记录巡查问题条数汇总!$B:$B,D22,记录巡查问题条数汇总!$E:$E) -> 0 | K23: =SUMIF(安全质量事故!$B:$B,D22,安全质量事故!$G:$G) -> 0 | L23: =COUNTIF(M23:AQ23,标准数据!$A$2)*标准数据!$B$2+COUNTIF(M23:AQ23,标准数据!$A$3)*标准数据!$B$3+COUNTIF(M23:AQ23,标准数据!$A$4)*标准数据!$B$4 -> 0 | AV23: =VLOOKUP(E23,[1]生产部!$C:$I,7,0) -> 包装 | AW23: =VLOOKUP(E23,[1]生产部!$C:$I,6,0) -> 4号楼1&2车间
A24: 4号楼1&2车间 | B24: 寡核苷酸厂房1D级区域 | C24: 助工 | D24: 王灿 | E24: ALS13025 | F24: 45497 | G24: =(L24+H24+I24+J24-K24) -> 0 | H24: =SUMIF(积分汇总!$B:$B,D23,积分汇总!$E:$E) -> 0 | I24: =SUMIF(记录巡查问题条数汇总!$B:$B,D23,记录巡查问题条数汇总!$E:$E) -> 0 | K24: =SUMIF(安全质量事故!$B:$B,D23,安全质量事故!$G:$G) -> 0 | L24: =COUNTIF(M24:AQ24,标准数据!$A$2)*标准数据!$B$2+COUNTIF(M24:AQ24,标准数据!$A$3)*标准数据!$B$3+COUNTIF(M24:AQ24,标准数据!$A$4)*标准数据!$B$4 -> 0 | AV24: =VLOOKUP(E24,[1]生产部!$C:$I,7,0) -> 班组 | AW24: =VLOOKUP(E24,[1]生产部!$C:$I,6,0) -> 4号楼1&2车间
A25: 4号楼1&2车间 | B25: 寡核苷酸厂房1D级区域 | C25: 助工 | D25: 杨俊 | E25: ALS13071 | F25: 45476 | G25: =(L25+H25+I25+J25-K25) -> 0 | H25: =SUMIF(积分汇总!$B:$B,D24,积分汇总!$E:$E) -> 0 | I25: =SUMIF(记录巡查问题条数汇总!$B:$B,D24,记录巡查问题条数汇总!$E:$E) -> 0 | K25: =SUMIF(安全质量事故!$B:$B,D24,安全质量事故!$G:$G) -> 0 | L25: =COUNTIF(M25:AQ25,标准数据!$A$2)*标准数据!$B$2+COUNTIF(M25:AQ25,标准数据!$A$3)*标准数据!$B$3+COUNTIF(M25:AQ25,标准数据!$A$4)*标准数据!$B$4 -> 0 | AV25: =VLOOKUP(E25,[1]生产部!$C:$I,7,0) -> 班组 | AW25: =VLOOKUP(E25,[1]生产部!$C:$I,6,0) -> 4号楼1&2车间
A26: 4号楼1&2车间 | B26: 寡核苷酸厂房1D级区域 | C26: 助工 | D26: 刘晓雨 | E26: ALS13176 | F26: 45490 | G26: =(L26+H26+I26+J26-K26) -> 0 | H26: =SUMIF(积分汇总!$B:$B,D25,积分汇总!$E:$E) -> 0 | I26: =SUMIF(记录巡查问题条数汇总!$B:$B,D25,记录巡查问题条数汇总!$E:$E) -> 0 | K26: =SUMIF(安全质量事故!$B:$B,D25,安全质量事故!$G:$G) -> 0 | L26: =COUNTIF(M26:AQ26,标准数据!$A$2)*标准数据!$B$2+COUNTIF(M26:AQ26,标准数据!$A$3)*标准数据!$B$3+COUNTIF(M26:AQ26,标准数据!$A$4)*标准数据!$B$4 -> 0 | AV26: =VLOOKUP(E26,[1]生产部!$C:$I,7,0) -> 项目组 | AW26: =VLOOKUP(E26,[1]生产部!$C:$I,6,0) -> 4号楼1&2车间
A27: 4号楼1&2车间 | B27: 寡核苷酸厂房1D级区域 | C27: 助工 | D27: 陈勇 | E27: ACT2599 | F27: 44396 | G27: =(L27+H27+I27+J27-K27) -> 0 | H27: =SUMIF(积分汇总!$B:$B,D26,积分汇总!$E:$E) -> 0 | I27: =SUMIF(记录巡查问题条数汇总!$B:$B,D26,记录巡查问题条数汇总!$E:$E) -> 0 | K27: =SUMIF(安全质量事故!$B:$B,D26,安全质量事故!$G:$G) -> 0 | L27: =COUNTIF(M27:AQ27,标准数据!$A$2)*标准数据!$B$2+COUNTIF(M27:AQ27,标准数据!$A$3)*标准数据!$B$3+COUNTIF(M27:AQ27,标准数据!$A$4)*标准数据!$B$4 -> 0 | AV27: =VLOOKUP(E27,[1]生产部!$C:$I,7,0) -> 项目组 | AW27: =VLOOKUP(E27,[1]生产部!$C:$I,6,0) -> 4号楼1&2车间
A28: 4号楼1&2车间 | B28: 寡核苷酸厂房1D级区域 | C28: 助工 | D28: 宁海龙 | E28: ALS13603 | F28: 45602 | G28: =(L28+H28+I28+J28-K28) -> 0 | H28: =SUMIF(积分汇总!$B:$B,D27,积分汇总!$E:$E) -> 0 | I28: =SUMIF(记录巡查问题条数汇总!$B:$B,D27,记录巡查问题条数汇总!$E:$E) -> 0 | K28: =SUMIF(安全质量事故!$B:$B,D27,安全质量事故!$G:$G) -> 0 | L28: =COUNTIF(M28:AQ28,标准数据!$A$2)*标准数据!$B$2+COUNTIF(M28:AQ28,标准数据!$A$3)*标准数据!$B$3+COUNTIF(M28:AQ28,标准数据!$A$4)*标准数据!$B$4 -> 0 | AV28: =VLOOKUP(E28,[1]生产部!$C:$I,7,0) -> 班组 | AW28: =VLOOKUP(E28,[1]生产部!$C:$I,6,0) -> 4号楼1&2车间
... A37: 4号楼1&2车间 | B37: 寡核苷酸厂房1D级区域 | C37: 助工 | D37: 陈亚新 | E37: ALS15254 | F37: 45971 | G37: =(L37+H37+I37+J37-K37) -> 0 | H37: =SUMIF(积分汇总!$B:$B,D36,积分汇总!$E:$E) -> 0 | I37: =SUMIF(记录巡查问题条数汇总!$B:$B,D36,记录巡查问题条数汇总!$E:$E) -> 0 | K37: =SUMIF(安全质量事故!$B:$B,D36,安全质量事故!$G:$G) -> 0 | L37: =COUNTIF(M37:AQ37,标准数据!$A$2)*标准数据!$B$2+COUNTIF(M37:AQ37,标准数据!$A$3)*标准数据!$B$3+COUNTIF(M37:AQ37,标准数据!$A$4)*标准数据!$B$4 -> 0 | AV37: =VLOOKUP(E37,[1]生产部!$C:$I,7,0) -> 常白 | AW37: =VLOOKUP(E37,[1]生产部!$C:$I,6,0) -> 4号楼1&2车间
A38: 4号楼1&2车间 | B38: 寡核苷酸厂房1D级区域 | C38: 助工 | D38: 王瑞沣 | E38: ALS15966 | F38: 46036 | G38: =(L38+H38+I38+J38-K38) -> 0 | H38: =SUMIF(积分汇总!$B:$B,,积分汇总!$E:$E) -> 0 | I38: =SUMIF(记录巡查问题条数汇总!$B:$B,,记录巡查问题条数汇总!$E:$E) -> 0 | K38: =SUMIF(安全质量事故!$B:$B,,安全质量事故!$G:$G) -> 0 | L38: =COUNTIF(M38:AQ38,标准数据!$A$2)*标准数据!$B$2+COUNTIF(M38:AQ38,标准数据!$A$3)*标准数据!$B$3+COUNTIF(M38:AQ38,标准数据!$A$4)*标准数据!$B$4 -> 0 | AV38: =VLOOKUP(E38,[1]生产部!$C:$I,7,0) -> 班组 | AW38: =VLOOKUP(E38,[1]生产部!$C:$I,6,0) -> 4号楼1&2车间
A39: 4号楼1&2车间 | B39: 寡核苷酸厂房1D级区域 | C39: 助工 | D39: 李贺 | E39: ABT0617 | F39: 45728 | G39: =(L39+H39+I39+J39-K39) -> 0 | H39: =SUMIF(积分汇总!$B:$B,D38,积分汇总!$E:$E) -> 0 | I39: =SUMIF(记录巡查问题条数汇总!$B:$B,D38,记录巡查问题条数汇总!$E:$E) -> 0 | K39: =SUMIF(安全质量事故!$B:$B,D38,安全质量事故!$G:$G) -> 0 | L39: =COUNTIF(M39:AQ39,标准数据!$A$2)*标准数据!$B$2+COUNTIF(M39:AQ39,标准数据!$A$3)*标准数据!$B$3+COUNTIF(M39:AQ39,标准数据!$A$4)*标准数据!$B$4 -> 0 | AV39: =VLOOKUP(E39,[1]生产部!$C:$I,7,0) -> 班组 | AW39: =VLOOKUP(E39,[1]生产部!$C:$I,6,0) -> 4号楼1&2车间
A40: 4号楼1&2车间 | B40: 寡核苷酸厂房1D级区域 | C40: 助工 | D40: 邢天宇 | E40: ABT0244 | F40: 41828 | G40: =(L40+H40+I40+J40-K40) -> 0 | H40: =SUMIF(积分汇总!$B:$B,D39,积分汇总!$E:$E) -> 0 | I40: =SUMIF(记录巡查问题条数汇总!$B:$B,D39,记录巡查问题条数汇总!$E:$E) -> 0 | K40: =SUMIF(安全质量事故!$B:$B,D39,安全质量事故!$G:$G) -> 0 | L40: =COUNTIF(M40:AQ40,标准数据!$A$2)*标准数据!$B$2+COUNTIF(M40:AQ40,标准数据!$A$3)*标准数据!$B$3+COUNTIF(M40:AQ40,标准数据!$A$4)*标准数据!$B$4 -> 0 | AV40: =VLOOKUP(E40,[1]生产部!$C:$I,7,0) -> 班组 | AW40: =VLOOKUP(E40,[1]生产部!$C:$I,6,0) -> 4号楼1&2车间
A41: 4号楼1&2车间 | B41: 寡核苷酸厂房1D级区域 | C41: 助工 | D41: 李玉修 | E41: ALS15337 | F41: 45980 | G41: =(L41+H41+I41+J41-K41) -> 0 | H41: =SUMIF(积分汇总!$B:$B,D40,积分汇总!$E:$E) -> 0 | I41: =SUMIF(记录巡查问题条数汇总!$B:$B,D40,记录巡查问题条数汇总!$E:$E) -> 0 | K41: =SUMIF(安全质量事故!$B:$B,D40,安全质量事故!$G:$G) -> 0 | L41: =COUNTIF(M41:AQ41,标准数据!$A$2)*标准数据!$B$2+COUNTIF(M41:AQ41,标准数据!$A$3)*标准数据!$B$3+COUNTIF(M41:AQ41,标准数据!$A$4)*标准数据!$B$4 -> 0 | AV41: =VLOOKUP(E41,[1]生产部!$C:$I,7,0) -> 班组 | AW41: =VLOOKUP(E41,[1]生产部!$C:$I,6,0) -> 4号楼1&2车间
A42: 4号楼1&2车间 | B42: 寡核苷酸厂房1D级区域 | C42: 助工 | D42: 戴显达 | E42: ALS15343 | F42: 45980 | G42: =(L42+H42+I42+J42-K42) -> 0 | H42: =SUMIF(积分汇总!$B:$B,D41,积分汇总!$E:$E) -> 0 | I42: =SUMIF(记录巡查问题条数汇总!$B:$B,D41,记录巡查问题条数汇总!$E:$E) -> 0 | K42: =SUMIF(安全质量事故!$B:$B,D41,安全质量事故!$G:$G) -> 0 | L42: =COUNTIF(M42:AQ42,标准数据!$A$2)*标准数据!$B$2+COUNTIF(M42:AQ42,标准数据!$A$3)*标准数据!$B$3+COUNTIF(M42:AQ42,标准数据!$A$4)*标准数据!$B$4 -> 0 | AV42: =VLOOKUP(E42,[1]生产部!$C:$I,7,0) -> 班组 | AW42: =VLOOKUP(E42,[1]生产部!$C:$I,6,0) -> 4号楼1&2车间
A43: 4号楼1&2车间 | B43: 寡核苷酸厂房1D级区域 | C43: 助工 | D43: 綦寿延 | E43: ALS15344 | F43: 45980 | G43: =(L43+H43+I43+J43-K43) -> 0 | H43: =SUMIF(积分汇总!$B:$B,D42,积分汇总!$E:$E) -> 0 | I43: =SUMIF(记录巡查问题条数汇总!$B:$B,D42,记录巡查问题条数汇总!$E:$E) -> 0 | K43: =SUMIF(安全质量事故!$B:$B,D42,安全质量事故!$G:$G) -> 0 | L43: =COUNTIF(M43:AQ43,标准数据!$A$2)*标准数据!$B$2+COUNTIF(M43:AQ43,标准数据!$A$3)*标准数据!$B$3+COUNTIF(M43:AQ43,标准数据!$A$4)*标准数据!$B$4 -> 0 | AV43: =VLOOKUP(E43,[1]生产部!$C:$I,7,0) -> 班组 | AW43: =VLOOKUP(E43,[1]生产部!$C:$I,6,0) -> 4号楼1&2车间
A44: 4号楼1&2车间 | B44: 寡核苷酸厂房1D级区域 | C44: 助工 | D44: 谭善文 | E44: ALS15674 | F44: 46006 | G44: =(L44+H44+I44+J44-K44) -> 0 | H44: =SUMIF(积分汇总!$B:$B,D43,积分汇总!$E:$E) -> 0 | I44: =SUMIF(记录巡查问题条数汇总!$B:$B,D43,记录巡查问题条数汇总!$E:$E) -> 0 | K44: =SUMIF(安全质量事故!$B:$B,D43,安全质量事故!$G:$G) -> 0 | L44: =COUNTIF(M44:AQ44,标准数据!$A$2)*标准数据!$B$2+COUNTIF(M44:AQ44,标准数据!$A$3)*标准数据!$B$3+COUNTIF(M44:AQ44,标准数据!$A$4)*标准数据!$B$4 -> 0 | AV44: =VLOOKUP(E44,[1]生产部!$C:$I,7,0) -> 班组 | AW44: =VLOOKUP(E44,[1]生产部!$C:$I,6,0) -> 4号楼1&2车间
A45: 4号楼1&2车间 | B45: 寡核苷酸厂房1D级区域 | C45: 助工 | D45: 袁浩 | E45: ALS16144 | F45: 46097 | G45: =(L45+H45+I45+J45-K45) -> 0 | H45: =SUMIF(积分汇总!$B:$B,D44,积分汇总!$E:$E) -> 0 | I45: =SUMIF(记录巡查问题条数汇总!$B:$B,D44,记录巡查问题条数汇总!$E:$E) -> 0 | K45: =SUMIF(安全质量事故!$B:$B,D44,安全质量事故!$G:$G) -> 0 | L45: =COUNTIF(M45:AQ45,标准数据!$A$2)*标准数据!$B$2+COUNTIF(M45:AQ45,标准数据!$A$3)*标准数据!$B$3+COUNTIF(M45:AQ45,标准数据!$A$4)*标准数据!$B$4 -> 0 | AV45: =VLOOKUP(E45,[1]生产部!$C:$I,7,0) -> 班组 | AW45: =VLOOKUP(E45,[1]生产部!$C:$I,6,0) -> 4号楼1&2车间
A46: 4号楼1&2车间 | B46: 寡核苷酸厂房1D级区域 | C46: 助工 | D46: 刘仁杰 | E46: ALS16309 | F46: 46120 | G46: =(L46+H46+I46+J46-K46) -> 0 | H46: =SUMIF(积分汇总!$B:$B,D45,积分汇总!$E:$E) -> 0 | I46: =SUMIF(记录巡查问题条数汇总!$B:$B,D45,记录巡查问题条数汇总!$E:$E) -> 0 | K46: =SUMIF(安全质量事故!$B:$B,D45,安全质量事故!$G:$G) -> 0 | L46: =COUNTIF(M46:AQ46,标准数据!$A$2)*标准数据!$B$2+COUNTIF(M46:AQ46,标准数据!$A$3)*标准数据!$B$3+COUNTIF(M46:AQ46,标准数据!$A$4)*标准数据!$B$4 -> 0 | AV46: =VLOOKUP(E46,[1]生产部!$C:$I,7,0) -> 常白 | AW46: =VLOOKUP(E46,[1]生产部!$C:$I,6,0) -> 4号楼1&2车间
A47: 4号楼1&2车间 | B47: 寡核苷酸厂房1D级区域 | C47: 助工 | D47: 王冰 | E47: ALS16318 | F47: 46120 | G47: =(L47+H47+I47+J47-K47) -> 0 | H47: =SUMIF(积分汇总!$B:$B,D46,积分汇总!$E:$E) -> 0 | I47: =SUMIF(记录巡查问题条数汇总!$B:$B,D46,记录巡查问题条数汇总!$E:$E) -> 0 | K47: =SUMIF(安全质量事故!$B:$B,D46,安全质量事故!$G:$G) -> 0 | L47: =COUNTIF(M47:AQ47,标准数据!$A$2)*标准数据!$B$2+COUNTIF(M47:AQ47,标准数据!$A$3)*标准数据!$B$3+COUNTIF(M47:AQ47,标准数据!$A$4)*标准数据!$B$4 -> 0 | AV47: =VLOOKUP(E47,[1]生产部!$C:$I,7,0) -> 班组 | AW47: =VLOOKUP(E47,[1]生产部!$C:$I,6,0) -> 4号楼1&2车间
A48: 4号楼1&2车间 | B48: 寡核苷酸厂房1D级区域 | C48: 助工 | D48: 罗泽泉 | E48: ALS16320 | F48: 46120 | G48: =(L48+H48+I48+J48-K48) -> 0 | H48: =SUMIF(积分汇总!$B:$B,D47,积分汇总!$E:$E) -> 0 | I48: =SUMIF(记录巡查问题条数汇总!$B:$B,D47,记录巡查问题条数汇总!$E:$E) -> 0 | K48: =SUMIF(安全质量事故!$B:$B,D47,安全质量事故!$G:$G) -> 0 | L48: =COUNTIF(M48:AQ48,标准数据!$A$2)*标准数据!$B$2+COUNTIF(M48:AQ48,标准数据!$A$3)*标准数据!$B$3+COUNTIF(M48:AQ48,标准数据!$A$4)*标准数据!$B$4 -> 0 | AV48: =VLOOKUP(E48,[1]生产部!$C:$I,7,0) -> 班组 | AW48: =VLOOKUP(E48,[1]生产部!$C:$I,6,0) -> 4号楼1&2车间
...

Sheet 说明
A1: 数据提供人 | B1: 安全质量奖 | C1: 一线人员sheet | D1: 副主任sheet
B2: 4#楼1&2车间： | C2: 田志勇 | D2: 刘其琛
B3: 4#楼3&4车间： | C3: 刘磊
B4: 11#楼CNC车间： | C4: 门学友 | D4: 杜永宝
B5: 11#楼D级区： | C5: 梁光强
B6: 5号楼： | C6: 冯恩利 | D6: 魏鹏
B7: 12号楼： | C7: 代海鑫 | D7: 姜彬
B8: 验证组 / DCS / 电子设备维护 / 合规&培训 ： | C8: 刘亚南 | D8: 刘亚南
B9: 环保设备设施 ： | C9: 刘文龙
B10: 外围/罐区/泵房： | C10: 赵艳春
B11: 清洗组： | C11: 陈正兴
B12: 安全组 | D12: 李国清
A13: 汇总说明
A14: 1 | B14: 月末或者月初整理安全质量奖，一线人员sheet和副主任sheet人员用员工编号与月底的人员明细表核对，删除离职的，补充新入职的人员；将日期修改后，内容清空，发给对应提报人，提供评价
A15: 2 | B15: 副主任级别sheet，添加好后面的设备使用率及对应挡位，钉钉发给对应该管理人员，问挡位是否有调整
A16: 3 | B16: 调生产设备部的不用管，调实验室的备注，调TJ1的加到TJ1核算表中

Sheet 积分汇总
A1: 积分汇总
A2: 车间 | B2: 姓名 | C2: 违规 | D2: 奖励 | E2: 积分合计 | F2: 备注
E3: =C3+D3 -> 0
E4: =C4+D4 -> 0
E5: =C5+D5 -> 0
E6: =C6+D6 -> 0
E7: =C7+D7 -> 0
E8: =C8+D8 -> 0
E9: =C9+D9 -> 0
E10: =C10+D10 -> 0
E11: =C11+D11 -> 0
E12: =C12+D12 -> 0
E13: =C13+D13 -> 0
E14: =C14+D14 -> 0
... E48: =C48+D48 -> 0
C49: =SUM(C3:C48) -> 0 | D49: =SUM(D3:D48) -> 0 | E49: =C49+D49 -> 0

Sheet 安全质量事故
A1: 车间 | B1: 责任人 | C1: 来源类别 | D1: 编号 | E1: 事故描述 | F1: 奖惩结果 | G1: 奖金扣除

Sheet 记录巡查问题条数汇总
A1: 车间 | B1: 姓名 | C1: 巡查条数汇总 | D1: 积分 | E1: 安全质量奖扣款

Sheet 标准数据
A1: 档位 | B1: 标准奖金 | C1: 人员占比
A2: A | B2: 35 | C2: 0.2
A3: B | B3: 15 | C3: 0.6
A4: C | B4: -5 | C4: 0.2
A10: 有API项目生产时，进入API工作的人员安全质量奖额外增加200元.
A11: >> 仅限一线人员(助工).
