Workbook

Sheet 副主任&工艺组长及其他
A1: 车间 | B1: 职务 | C1: 姓名 | D1: 员工编号 | E1: 入职日期 | F1: 实际奖金合计 | G1: 日常巡查扣款 | H1: 记录巡查扣款 | I1: 定点摄影最佳区域和最差区域评比 | J1: 奖惩 | K1: 出勤率 | L1: 调整后奖金 | M1: 调整后档位 | N1: 基础挡位 | O1: 计件批次 （参考） | P1: 设备体积利用率 | Q1: 备注
A2: 4号楼1&2车间 | B2: 副主任 | C2: 刘震 | D2: ALS1988 | E2: 42073 | F2: =(L2*K2+G2+H2+I2-J2) -> 600 | G2: =SUMIF(积分汇总!$B:$B,'副主任&工艺组长及其他'!C2,积分汇总!$E:$E) -> 0 | H2: =SUMIF(记录巡查问题条数汇总!$B:$B,'副主任&工艺组长及其他'!C2,记录巡查问题条数汇总!$E:$E) -> 0 | J2: =SUMIF(安全质量事故!$B:$B,'副主任&工艺组长及其他'!C2,安全质量事故!$G:$G) -> 0 | K2: 1 | L2: =HLOOKUP(M2,$A$143:$H$144,2) -> 600 | M2: A | N2: B | O2: 187.77 | P2: 0.471 | R2: =VLOOKUP(D2,[1]生产部!$C:$C,1,0) -> ALS1988
A3: 4号楼1&2车间 | B3: 副主任 | C3: 王鑫（ALS8215） | D3: ALS8215 | E3: 44431 | F3: =(L3*K3+G3+H3+I3-J3) -> 600 | G3: =SUMIF(积分汇总!$B:$B,'副主任&工艺组长及其他'!C3,积分汇总!$E:$E) -> 0 | H3: =SUMIF(记录巡查问题条数汇总!$B:$B,'副主任&工艺组长及其他'!C3,记录巡查问题条数汇总!$E:$E) -> 0 | J3: =SUMIF(安全质量事故!$B:$B,'副主任&工艺组长及其他'!C3,安全质量事故!$G:$G) -> 0 | K3: 1 | L3: =HLOOKUP(M3,$A$143:$H$144,2) -> 600 | M3: A | R3: =VLOOKUP(D3,[1]生产部!$C:$C,1,0) -> ALS8215
A4: 4号楼1&2车间 | B4: 工艺组长 | C4: 白春江 | D4: FX2679 | E4: 42933 | F4: =(L4*K4+G4+H4+I4-J4) -> 600 | G4: =SUMIF(积分汇总!$B:$B,'副主任&工艺组长及其他'!C4,积分汇总!$E:$E) -> 0 | H4: =SUMIF(记录巡查问题条数汇总!$B:$B,'副主任&工艺组长及其他'!C4,记录巡查问题条数汇总!$E:$E) -> 0 | J4: =SUMIF(安全质量事故!$B:$B,'副主任&工艺组长及其他'!C4,安全质量事故!$G:$G) -> 0 | K4: 1 | L4: =HLOOKUP(M4,$A$143:$H$144,2) -> 600 | M4: A | R4: =VLOOKUP(D4,[1]生产部!$C:$C,1,0) -> FX2679
A5: 4号楼1&2车间 | B5: 工艺组长 | C5: 罗林 | D5: ADH5191 | E5: 44677 | F5: =(L5*K5+G5+H5+I5-J5) -> 600 | G5: =SUMIF(积分汇总!$B:$B,'副主任&工艺组长及其他'!C5,积分汇总!$E:$E) -> 0 | H5: =SUMIF(记录巡查问题条数汇总!$B:$B,'副主任&工艺组长及其他'!C5,记录巡查问题条数汇总!$E:$E) -> 0 | J5: =SUMIF(安全质量事故!$B:$B,'副主任&工艺组长及其他'!C5,安全质量事故!$G:$G) -> 0 | K5: 1 | L5: =HLOOKUP(M5,$A$143:$H$144,2) -> 600 | M5: A | R5: =VLOOKUP(D5,[1]生产部!$C:$C,1,0) -> ADH5191
A6: 4号楼1&2车间 | B6: 工艺组长 | C6: 韩智慧 | D6: ALS10146 | E6: 44755 | F6: =(L6*K6+G6+H6+I6-J6) -> 400 | G6: =SUMIF(积分汇总!$B:$B,'副主任&工艺组长及其他'!C6,积分汇总!$E:$E) -> 0 | H6: =SUMIF(记录巡查问题条数汇总!$B:$B,'副主任&工艺组长及其他'!C6,记录巡查问题条数汇总!$E:$E) -> 0 | J6: =SUMIF(安全质量事故!$B:$B,'副主任&工艺组长及其他'!C6,安全质量事故!$G:$G) -> 0 | K6: 1 | L6: =HLOOKUP(M6,$A$143:$H$144,2) -> 400 | M6: B | R6: =VLOOKUP(D6,[1]生产部!$C:$C,1,0) -> ALS10146
A7: 4号楼1&2车间 | B7: 工艺组长 | C7: 陈雍 | D7: BDH0641 | E7: 44732 | F7: =(L7*K7+G7+H7+I7-J7) -> 400 | G7: =SUMIF(积分汇总!$B:$B,'副主任&工艺组长及其他'!C7,积分汇总!$E:$E) -> 0 | H7: =SUMIF(记录巡查问题条数汇总!$B:$B,'副主任&工艺组长及其他'!C7,记录巡查问题条数汇总!$E:$E) -> 0 | J7: =SUMIF(安全质量事故!$B:$B,'副主任&工艺组长及其他'!C7,安全质量事故!$G:$G) -> 0 | K7: 1 | L7: =HLOOKUP(M7,$A$143:$H$144,2) -> 400 | M7: B | R7: =VLOOKUP(D7,[1]生产部!$C:$C,1,0) -> BDH0641
A8: 4号楼1&2车间 | B8: 工艺组长 | C8: 孙福林 | D8: ALS16047 | E8: 46057 | F8: =(L8*K8+G8+H8+I8-J8) -> 400 | G8: =SUMIF(积分汇总!$B:$B,'副主任&工艺组长及其他'!C8,积分汇总!$E:$E) -> 0 | H8: =SUMIF(记录巡查问题条数汇总!$B:$B,'副主任&工艺组长及其他'!C8,记录巡查问题条数汇总!$E:$E) -> 0 | J8: =SUMIF(安全质量事故!$B:$B,'副主任&工艺组长及其他'!C8,安全质量事故!$G:$G) -> 0 | K8: 1 | L8: =HLOOKUP(M8,$A$143:$H$144,2) -> 400 | M8: B | R8: =VLOOKUP(D8,[1]生产部!$C:$C,1,0) -> ALS16047
A9: 4号楼1&2车间 | B9: 工程师 | C9: 张兴海 | D9: ALS12958 | E9: 45448 | F9: =(L9*K9+G9+H9+I9-J9) -> 400 | G9: =SUMIF(积分汇总!$B:$B,'副主任&工艺组长及其他'!C9,积分汇总!$E:$E) -> 0 | H9: =SUMIF(记录巡查问题条数汇总!$B:$B,'副主任&工艺组长及其他'!C9,记录巡查问题条数汇总!$E:$E) -> 0 | J9: =SUMIF(安全质量事故!$B:$B,'副主任&工艺组长及其他'!C9,安全质量事故!$G:$G) -> 0 | K9: 1 | L9: =HLOOKUP(M9,$A$143:$H$144,2) -> 400 | M9: B | R9: =VLOOKUP(D9,[1]生产部!$C:$C,1,0) -> ALS12958
A10: 4号楼1&2车间 | B10: 工程师 | C10: 刘太安 | D10: FX2743 | E10: 43237 | F10: =(L10*K10+G10+H10+I10-J10) -> 400 | G10: =SUMIF(积分汇总!$B:$B,'副主任&工艺组长及其他'!C10,积分汇总!$E:$E) -> 0 | H10: =SUMIF(记录巡查问题条数汇总!$B:$B,'副主任&工艺组长及其他'!C10,记录巡查问题条数汇总!$E:$E) -> 0 | J10: =SUMIF(安全质量事故!$B:$B,'副主任&工艺组长及其他'!C10,安全质量事故!$G:$G) -> 0 | K10: 1 | L10: =HLOOKUP(M10,$A$143:$H$144,2) -> 400 | M10: B | Q10: 2026/04/10借调TJ4 | R10: =VLOOKUP(D10,[1]生产部!$C:$C,1,0) -> FX2743
A11: 4号楼1&2车间 | B11: 工程师 | C11: 翟鹏飞 | D11: ALS17021 | E11: 46176 | F11: =(L11*K11+G11+H11+I11-J11) -> 400 | G11: =SUMIF(积分汇总!$B:$B,'副主任&工艺组长及其他'!C11,积分汇总!$E:$E) -> 0 | H11: =SUMIF(记录巡查问题条数汇总!$B:$B,'副主任&工艺组长及其他'!C11,记录巡查问题条数汇总!$E:$E) -> 0 | J11: =SUMIF(安全质量事故!$B:$B,'副主任&工艺组长及其他'!C11,安全质量事故!$G:$G) -> 0 | K11: 1 | L11: =HLOOKUP(M11,$A$143:$H$144,2) -> 400 | M11: B | Q11: 2026/04/10借调TJ4 | R11: =VLOOKUP(D11,[1]生产部!$C:$C,1,0) -> ALS17021
A12: 4号楼1&2车间 | B12: 助理工程师 | C12: 赵凯 | D12: ALS11919 | E12: 45042 | F12: =(L12*K12+G12+H12+I12-J12) -> 400 | G12: =SUMIF(积分汇总!$B:$B,'副主任&工艺组长及其他'!C12,积分汇总!$E:$E) -> 0 | H12: =SUMIF(记录巡查问题条数汇总!$B:$B,'副主任&工艺组长及其他'!C12,记录巡查问题条数汇总!$E:$E) -> 0 | J12: =SUMIF(安全质量事故!$B:$B,'副主任&工艺组长及其他'!C12,安全质量事故!$G:$G) -> 0 | K12: 1 | L12: =HLOOKUP(M12,$A$143:$H$144,2) -> 400 | M12: B | R12: =VLOOKUP(D12,[1]生产部!$C:$C,1,0) -> ALS11919
A13: 4号楼1&2车间 | B13: 助理工程师 | C13: 刘简 | D13: ALS17018 | E13: 46176 | F13: =(L13*K13+G13+H13+I13-J13) -> 400 | G13: =SUMIF(积分汇总!$B:$B,'副主任&工艺组长及其他'!C13,积分汇总!$E:$E) -> 0 | H13: =SUMIF(记录巡查问题条数汇总!$B:$B,'副主任&工艺组长及其他'!C13,记录巡查问题条数汇总!$E:$E) -> 0 | J13: =SUMIF(安全质量事故!$B:$B,'副主任&工艺组长及其他'!C13,安全质量事故!$G:$G) -> 0 | K13: 1 | L13: =HLOOKUP(M13,$A$143:$H$144,2) -> 400 | M13: B | R13: =VLOOKUP(D13,[1]生产部!$C:$C,1,0) -> ALS17018
A14: 4号楼1&2车间 | B14: 助理工程师 | C14: 宋京硕 | D14: ALS17114 | E14: 46183 | F14: =(L14*K14+G14+H14+I14-J14)/30*20 -> 266.66667 | G14: =SUMIF(积分汇总!$B:$B,'副主任&工艺组长及其他'!C14,积分汇总!$E:$E) -> 0 | H14: =SUMIF(记录巡查问题条数汇总!$B:$B,'副主任&工艺组长及其他'!C14,记录巡查问题条数汇总!$E:$E) -> 0 | J14: =SUMIF(安全质量事故!$B:$B,'副主任&工艺组长及其他'!C14,安全质量事故!$G:$G) -> 0 | K14: 1 | L14: =HLOOKUP(M14,$A$143:$H$144,2) -> 400 | M14: B | R14: =VLOOKUP(D14,[1]生产部!$C:$C,1,0) -> ALS17114
A15: 4号楼1&2车间 | B15: 助理工程师 | C15: 王富星 | D15: ALS15894 | E15: 46027 | F15: =(L15*K15+G15+H15+I15-J15) -> 400 | G15: =SUMIF(积分汇总!$B:$B,'副主任&工艺组长及其他'!C15,积分汇总!$E:$E) -> 0 | H15: =SUMIF(记录巡查问题条数汇总!$B:$B,'副主任&工艺组长及其他'!C15,记录巡查问题条数汇总!$E:$E) -> 0 | J15: =SUMIF(安全质量事故!$B:$B,'副主任&工艺组长及其他'!C15,安全质量事故!$G:$G) -> 0 | K15: 1 | L15: =HLOOKUP(M15,$A$143:$H$144,2) -> 400 | M15: B | Q15: 师傅 陈玉慧；调实验室学习制备 | R15: =VLOOKUP(D15,[1]生产部!$C:$C,1,0) -> ALS15894
A16: 4号楼1&2车间 | B16: 助理工程师 | C16: 王嘉俊 | D16: ALS15896 | E16: 46027 | F16: =(L16*K16+G16+H16+I16-J16) -> 400 | G16: =SUMIF(积分汇总!$B:$B,'副主任&工艺组长及其他'!C16,积分汇总!$E:$E) -> 0 | H16: =SUMIF(记录巡查问题条数汇总!$B:$B,'副主任&工艺组长及其他'!C16,记录巡查问题条数汇总!$E:$E) -> 0 | J16: =SUMIF(安全质量事故!$B:$B,'副主任&工艺组长及其他'!C16,安全质量事故!$G:$G) -> 0 | K16: 1 | L16: =HLOOKUP(M16,$A$143:$H$144,2) -> 400 | M16: B | Q16: 2026/06/30离职 | R16: =VLOOKUP(D16,[1]生产部!$C:$C,1,0) -> ALS15896
A17: 4号楼1&2车间 | B17: 助理工程师 | C17: 杨博硕 | D17: ALS15895 | E17: 46027 | F17: =(L17*K17+G17+H17+I17-J17) -> 400 | G17: =SUMIF(积分汇总!$B:$B,'副主任&工艺组长及其他'!C17,积分汇总!$E:$E) -> 0 | H17: =SUMIF(记录巡查问题条数汇总!$B:$B,'副主任&工艺组长及其他'!C17,记录巡查问题条数汇总!$E:$E) -> 0 | J17: =SUMIF(安全质量事故!$B:$B,'副主任&工艺组长及其他'!C17,安全质量事故!$G:$G) -> 0 | K17: 1 | L17: =HLOOKUP(M17,$A$143:$H$144,2) -> 400 | M17: B | Q17: 师傅 陈玉慧；调实验室学习制备 | R17: =VLOOKUP(D17,[1]生产部!$C:$C,1,0) -> ALS15895
A18: 4号楼1&2车间 | B18: 助理工程师 | C18: 白子洋 | D18: ALS15897 | E18: 46027 | F18: =(L18*K18+G18+H18+I18-J18) -> 400 | G18: =SUMIF(积分汇总!$B:$B,'副主任&工艺组长及其他'!C18,积分汇总!$E:$E) -> 0 | H18: =SUMIF(记录巡查问题条数汇总!$B:$B,'副主任&工艺组长及其他'!C18,记录巡查问题条数汇总!$E:$E) -> 0 | J18: =SUMIF(安全质量事故!$B:$B,'副主任&工艺组长及其他'!C18,安全质量事故!$G:$G) -> 0 | K18: 1 | L18: =HLOOKUP(M18,$A$143:$H$144,2) -> 400 | M18: B | Q18: 师傅 陈玉慧；调实验室学习制备 | R18: =VLOOKUP(D18,[1]生产部!$C:$C,1,0) -> ALS15897
A19: 4号楼1&2车间 | B19: 操作工 | C19: 赵申澳 | D19: ALS14195 | E19: 45833 | F19: =(L19*K19+G19+H19+I19-J19) -> 400 | G19: =SUMIF(积分汇总!$B:$B,'副主任&工艺组长及其他'!C19,积分汇总!$E:$E) -> 0 | H19: =SUMIF(记录巡查问题条数汇总!$B:$B,'副主任&工艺组长及其他'!C19,记录巡查问题条数汇总!$E:$E) -> 0 | J19: =SUMIF(安全质量事故!$B:$B,'副主任&工艺组长及其他'!C19,安全质量事故!$G:$G) -> 0 | K19: 1 | L19: =HLOOKUP(M19,$A$143:$H$144,2) -> 400 | M19: B | R19: =VLOOKUP(D19,[1]生产部!$C:$C,1,0) -> ALS14195
A20: 4号楼1&2车间 | B20: 操作工 | C20: 张家园 | D20: ALS15823 | E20: 46029 | F20: =(L20*K20+G20+H20+I20-J20) -> 400 | G20: =SUMIF(积分汇总!$B:$B,'副主任&工艺组长及其他'!C20,积分汇总!$E:$E) -> 0 | H20: =SUMIF(记录巡查问题条数汇总!$B:$B,'副主任&工艺组长及其他'!C20,记录巡查问题条数汇总!$E:$E) -> 0 | J20: =SUMIF(安全质量事故!$B:$B,'副主任&工艺组长及其他'!C20,安全质量事故!$G:$G) -> 0 | K20: 1 | L20: =HLOOKUP(M20,$A$143:$H$144,2) -> 400 | M20: B | R20: =VLOOKUP(D20,[1]生产部!$C:$C,1,0) -> ALS15823
A21: 4号楼3&4车间 | B21: 副主任 | C21: 王家伟 | D21: ACT2027 | E21: 44125 | F21: =(L21*K21+G21+H21+I21-J21) -> 600 | G21: =SUMIF(积分汇总!$B:$B,'副主任&工艺组长及其他'!C21,积分汇总!$E:$E) -> 0 | H21: =SUMIF(记录巡查问题条数汇总!$B:$B,'副主任&工艺组长及其他'!C21,记录巡查问题条数汇总!$E:$E) -> 0 | J21: =SUMIF(安全质量事故!$B:$B,'副主任&工艺组长及其他'!C21,安全质量事故!$G:$G) -> 0 | K21: 1 | L21: =HLOOKUP(M21,$A$143:$H$144,2) -> 600 | M21: A | R21: =VLOOKUP(D21,[1]生产部!$C:$C,1,0) -> ACT2027
A22: 4号楼3&4车间 | B22: 副主任 | C22: 杨欢（ALS7213） | D22: ALS7213 | E22: 44272 | F22: =(L22*K22+G22+H22+I22-J22) -> 400 | G22: =SUMIF(积分汇总!$B:$B,'副主任&工艺组长及其他'!C22,积分汇总!$E:$E) -> 0 | H22: =SUMIF(记录巡查问题条数汇总!$B:$B,'副主任&工艺组长及其他'!C22,记录巡查问题条数汇总!$E:$E) -> 0 | J22: =SUMIF(安全质量事故!$B:$B,'副主任&工艺组长及其他'!C22,安全质量事故!$G:$G) -> 0 | K22: 1 | L22: =HLOOKUP(M22,$A$143:$H$144,2) -> 400 | M22: B | R22: =VLOOKUP(D22,[1]生产部!$C:$C,1,0) -> ALS7213
A23: 4号楼3&4车间 | B23: 副主任 | C23: 李国强 | D23: ALS6830 | E23: 44139 | F23: =(L23*K23+G23+H23+I23-J23) -> 600 | G23: =SUMIF(积分汇总!$B:$B,'副主任&工艺组长及其他'!C23,积分汇总!$E:$E) -> 0 | H23: =SUMIF(记录巡查问题条数汇总!$B:$B,'副主任&工艺组长及其他'!C23,记录巡查问题条数汇总!$E:$E) -> 0 | J23: =SUMIF(安全质量事故!$B:$B,'副主任&工艺组长及其他'!C23,安全质量事故!$G:$G) -> 0 | K23: 1 | L23: =HLOOKUP(M23,$A$143:$H$144,2) -> 600 | M23: A | R23: =VLOOKUP(D23,[1]生产部!$C:$C,1,0) -> ALS6830
A24: 4号楼3&4车间 | B24: 工艺组长 | C24: 朱晔 | D24: ALS3598 | E24: 42926 | F24: =(L24*K24+G24+H24+I24-J24) -> 400 | G24: =SUMIF(积分汇总!$B:$B,'副主任&工艺组长及其他'!C24,积分汇总!$E:$E) -> 0 | H24: =SUMIF(记录巡查问题条数汇总!$B:$B,'副主任&工艺组长及其他'!C24,记录巡查问题条数汇总!$E:$E) -> 0 | J24: =SUMIF(安全质量事故!$B:$B,'副主任&工艺组长及其他'!C24,安全质量事故!$G:$G) -> 0 | K24: 1 | L24: =HLOOKUP(M24,$A$143:$H$144,2) -> 400 | M24: B | R24: =VLOOKUP(D24,[1]生产部!$C:$C,1,0) -> ALS3598
A25: 4号楼3&4车间 | B25: 工艺组长 | C25: 郭纹建 | D25: FX2691 | E25: 42972 | F25: =(L25*K25+G25+H25+I25-J25) -> 400 | G25: =SUMIF(积分汇总!$B:$B,'副主任&工艺组长及其他'!C25,积分汇总!$E:$E) -> 0 | H25: =SUMIF(记录巡查问题条数汇总!$B:$B,'副主任&工艺组长及其他'!C25,记录巡查问题条数汇总!$E:$E) -> 0 | J25: =SUMIF(安全质量事故!$B:$B,'副主任&工艺组长及其他'!C25,安全质量事故!$G:$G) -> 0 | K25: 1 | L25: =HLOOKUP(M25,$A$143:$H$144,2) -> 400 | M25: B | R25: =VLOOKUP(D25,[1]生产部!$C:$C,1,0) -> FX2691
A26: 4号楼3&4车间 | B26: 工艺组长 | C26: 刘旺 | D26: ALS10155 | E26: 44755 | F26: =(L26*K26+G26+H26+I26-J26) -> 400 | G26: =SUMIF(积分汇总!$B:$B,'副主任&工艺组长及其他'!C26,积分汇总!$E:$E) -> 0 | H26: =SUMIF(记录巡查问题条数汇总!$B:$B,'副主任&工艺组长及其他'!C26,记录巡查问题条数汇总!$E:$E) -> 0 | J26: =SUMIF(安全质量事故!$B:$B,'副主任&工艺组长及其他'!C26,安全质量事故!$G:$G) -> 0 | K26: 1 | L26: =HLOOKUP(M26,$A$143:$H$144,2) -> 400 | M26: B | R26: =VLOOKUP(D26,[1]生产部!$C:$C,1,0) -> ALS10155
A27: 4号楼3&4车间 | B27: 工艺组长 | C27: 晏和聪 | D27: ALS10332 | E27: 44734 | F27: =(L27*K27+G27+H27+I27-J27) -> 400 | G27: =SUMIF(积分汇总!$B:$B,'副主任&工艺组长及其他'!C27,积分汇总!$E:$E) -> 0 | H27: =SUMIF(记录巡查问题条数汇总!$B:$B,'副主任&工艺组长及其他'!C27,记录巡查问题条数汇总!$E:$E) -> 0 | J27: =SUMIF(安全质量事故!$B:$B,'副主任&工艺组长及其他'!C27,安全质量事故!$G:$G) -> 0 | K27: 1 | L27: =HLOOKUP(M27,$A$143:$H$144,2) -> 400 | M27: B | R27: =VLOOKUP(D27,[1]生产部!$C:$C,1,0) -> ALS10332
A28: 4号楼3&4车间 | B28: 工艺组长 | C28: 李天宇 | D28: ALS10153 | E28: 44755 | F28: =(L28*K28+G28+H28+I28-J28) -> 600 | G28: =SUMIF(积分汇总!$B:$B,'副主任&工艺组长及其他'!C28,积分汇总!$E:$E) -> 0 | H28: =SUMIF(记录巡查问题条数汇总!$B:$B,'副主任&工艺组长及其他'!C28,记录巡查问题条数汇总!$E:$E) -> 0 | J28: =SUMIF(安全质量事故!$B:$B,'副主任&工艺组长及其他'!C28,安全质量事故!$G:$G) -> 0 | K28: 1 | L28: =HLOOKUP(M28,$A$143:$H$144,2) -> 600 | M28: A | R28: =VLOOKUP(D28,[1]生产部!$C:$C,1,0) -> ALS10153
A29: 4号楼3&4车间 | B29: 工艺组长 | C29: 陈博文 | D29: ALS7875 | E29: 44389 | F29: =(L29*K29+G29+H29+I29-J29) -> 400 | G29: =SUMIF(积分汇总!$B:$B,'副主任&工艺组长及其他'!C29,积分汇总!$E:$E) -> 0 | H29: =SUMIF(记录巡查问题条数汇总!$B:$B,'副主任&工艺组长及其他'!C29,记录巡查问题条数汇总!$E:$E) -> 0 | J29: =SUMIF(安全质量事故!$B:$B,'副主任&工艺组长及其他'!C29,安全质量事故!$G:$G) -> 0 | K29: 1 | L29: =HLOOKUP(M29,$A$143:$H$144,2) -> 400 | M29: B | R29: =VLOOKUP(D29,[1]生产部!$C:$C,1,0) -> ALS7875
A30: 4号楼3&4车间 | B30: 工艺组长 | C30: 谢文忠 | D30: ALS8245 | E30: 44433 | F30: =(L30*K30+G30+H30+I30-J30) -> 400 | G30: =SUMIF(积分汇总!$B:$B,'副主任&工艺组长及其他'!C30,积分汇总!$E:$E) -> 0 | H30: =SUMIF(记录巡查问题条数汇总!$B:$B,'副主任&工艺组长及其他'!C30,记录巡查问题条数汇总!$E:$E) -> 0 | J30: =SUMIF(安全质量事故!$B:$B,'副主任&工艺组长及其他'!C30,安全质量事故!$G:$G) -> 0 | K30: 1 | L30: =HLOOKUP(M30,$A$143:$H$144,2) -> 400 | M30: B | R30: =VLOOKUP(D30,[1]生产部!$C:$C,1,0) -> ALS8245
... A34: 4号楼3&4车间 | B34: 工程师 | C34: 刘振 | D34: ALS16970 | E34: 46169 | F34: =(L34*K34+G34+H34+I34-J34) -> 400 | G34: =SUMIF(积分汇总!$B:$B,'副主任&工艺组长及其他'!C34,积分汇总!$E:$E) -> 0 | H34: =SUMIF(记录巡查问题条数汇总!$B:$B,'副主任&工艺组长及其他'!C34,记录巡查问题条数汇总!$E:$E) -> 0 | J34: =SUMIF(安全质量事故!$B:$B,'副主任&工艺组长及其他'!C34,安全质量事故!$G:$G) -> 0 | K34: 1 | L34: =HLOOKUP(M34,$A$143:$H$144,2) -> 400 | M34: B | R34: =VLOOKUP(D34,[1]生产部!$C:$C,1,0) -> ALS16970
A35: 4号楼3&4车间 | B35: 助理工程师 | C35: 王凯 | D35: LFX573 | E35: 44389 | F35: =(L35*K35+G35+H35+I35-J35) -> 400 | G35: =SUMIF(积分汇总!$B:$B,'副主任&工艺组长及其他'!C35,积分汇总!$E:$E) -> 0 | H35: =SUMIF(记录巡查问题条数汇总!$B:$B,'副主任&工艺组长及其他'!C35,记录巡查问题条数汇总!$E:$E) -> 0 | J35: =SUMIF(安全质量事故!$B:$B,'副主任&工艺组长及其他'!C35,安全质量事故!$G:$G) -> 0 | K35: 1 | L35: =HLOOKUP(M35,$A$143:$H$144,2) -> 400 | M35: B | Q35: 2026/04/10借调TJ4 | R35: =VLOOKUP(D35,[1]生产部!$C:$C,1,0) -> LFX573
A36: 4号楼3&4车间 | B36: 助理工程师 | C36: 阴策 | D36: ALS16847 | E36: 46160 | F36: =(L36*K36+G36+H36+I36-J36) -> 400 | G36: =SUMIF(积分汇总!$B:$B,'副主任&工艺组长及其他'!C36,积分汇总!$E:$E) -> 0 | H36: =SUMIF(记录巡查问题条数汇总!$B:$B,'副主任&工艺组长及其他'!C36,记录巡查问题条数汇总!$E:$E) -> 0 | J36: =SUMIF(安全质量事故!$B:$B,'副主任&工艺组长及其他'!C36,安全质量事故!$G:$G) -> 0 | K36: 1 | L36: =HLOOKUP(M36,$A$143:$H$144,2) -> 400 | M36: B | R36: =VLOOKUP(D36,[1]生产部!$C:$C,1,0) -> ALS16847
A37: 4号楼3&4车间 | B37: 助理工程师 | C37: 宋景耀 | D37: ALS16005 | E37: 46043 | F37: =(L37*K37+G37+H37+I37-J37) -> 400 | G37: =SUMIF(积分汇总!$B:$B,'副主任&工艺组长及其他'!C37,积分汇总!$E:$E) -> 0 | H37: =SUMIF(记录巡查问题条数汇总!$B:$B,'副主任&工艺组长及其他'!C37,记录巡查问题条数汇总!$E:$E) -> 0 | J37: =SUMIF(安全质量事故!$B:$B,'副主任&工艺组长及其他'!C37,安全质量事故!$G:$G) -> 0 | K37: 1 | L37: =HLOOKUP(M37,$A$143:$H$144,2) -> 400 | M37: B | Q37: 师傅 皮轶杰；调实验室学习制备 | R37: =VLOOKUP(D37,[1]生产部!$C:$C,1,0) -> ALS16005
A38: 4号楼3&4车间 | B38: 助理工程师 | C38: 张佳佳 | D38: ALS15926 | E38: 46106 | F38: =(L38*K38+G38+H38+I38-J38) -> 400 | G38: =SUMIF(积分汇总!$B:$B,'副主任&工艺组长及其他'!C38,积分汇总!$E:$E) -> 0 | H38: =SUMIF(记录巡查问题条数汇总!$B:$B,'副主任&工艺组长及其他'!C38,记录巡查问题条数汇总!$E:$E) -> 0 | J38: =SUMIF(安全质量事故!$B:$B,'副主任&工艺组长及其他'!C38,安全质量事故!$G:$G) -> 0 | K38: 1 | L38: =HLOOKUP(M38,$A$143:$H$144,2) -> 400 | M38: B | Q38: 师傅 皮轶杰；调实验室学习制备 | R38: =VLOOKUP(D38,[1]生产部!$C:$C,1,0) -> ALS15926
A39: 4号楼3&4车间 | B39: 助理工程师 | C39: 柳至阳 | D39: ALS15911 | E39: 46029 | F39: =(L39*K39+G39+H39+I39-J39) -> 400 | G39: =SUMIF(积分汇总!$B:$B,'副主任&工艺组长及其他'!C39,积分汇总!$E:$E) -> 0 | H39: =SUMIF(记录巡查问题条数汇总!$B:$B,'副主任&工艺组长及其他'!C39,记录巡查问题条数汇总!$E:$E) -> 0 | J39: =SUMIF(安全质量事故!$B:$B,'副主任&工艺组长及其他'!C39,安全质量事故!$G:$G) -> 0 | K39: 1 | L39: =HLOOKUP(M39,$A$143:$H$144,2) -> 400 | M39: B | Q39: 师傅 王城；调实验室学习制备 | R39: =VLOOKUP(D39,[1]生产部!$C:$C,1,0) -> ALS15911
A40: 4号楼3&4车间 | B40: 助理工程师 | C40: 唐凯 | D40: ALS15913 | E40: 46029 | F40: =(L40*K40+G40+H40+I40-J40) -> 200 | G40: =SUMIF(积分汇总!$B:$B,'副主任&工艺组长及其他'!C40,积分汇总!$E:$E) -> 0 | H40: =SUMIF(记录巡查问题条数汇总!$B:$B,'副主任&工艺组长及其他'!C40,记录巡查问题条数汇总!$E:$E) -> 0 | J40: =SUMIF(安全质量事故!$B:$B,'副主任&工艺组长及其他'!C40,安全质量事故!$G:$G) -> 0 | K40: 1 | L40: =HLOOKUP(M40,$A$143:$H$144,2) -> 200 | M40: C | Q40: 2026/06/30离职 | R40: =VLOOKUP(D40,[1]生产部!$C:$C,1,0) -> ALS15913
A41: 4号楼3&4车间 | B41: 助理工程师 | C41: 罗江邻 | D41: ALS15910 | E41: 46029 | F41: =(L41*K41+G41+H41+I41-J41) -> 400 | G41: =SUMIF(积分汇总!$B:$B,'副主任&工艺组长及其他'!C41,积分汇总!$E:$E) -> 0 | H41: =SUMIF(记录巡查问题条数汇总!$B:$B,'副主任&工艺组长及其他'!C41,记录巡查问题条数汇总!$E:$E) -> 0 | J41: =SUMIF(安全质量事故!$B:$B,'副主任&工艺组长及其他'!C41,安全质量事故!$G:$G) -> 0 | K41: 1 | L41: =HLOOKUP(M41,$A$143:$H$144,2) -> 400 | M41: B | Q41: 师傅 宁海龙；调实验室学习制备 | R41: =VLOOKUP(D41,[1]生产部!$C:$C,1,0) -> ALS15910
A42: 4号楼3&4车间 | B42: 助理工程师 | C42: 杨博皓 | D42: ALS15912 | E42: 46029 | F42: =(L42*K42+G42+H42+I42-J42) -> 400 | G42: =SUMIF(积分汇总!$B:$B,'副主任&工艺组长及其他'!C42,积分汇总!$E:$E) -> 0 | H42: =SUMIF(记录巡查问题条数汇总!$B:$B,'副主任&工艺组长及其他'!C42,记录巡查问题条数汇总!$E:$E) -> 0 | J42: =SUMIF(安全质量事故!$B:$B,'副主任&工艺组长及其他'!C42,安全质量事故!$G:$G) -> 0 | K42: 1 | L42: =HLOOKUP(M42,$A$143:$H$144,2) -> 400 | M42: B | Q42: 师傅 张鹏飞；调实验室学习制备 | R42: =VLOOKUP(D42,[1]生产部!$C:$C,1,0) -> ALS15912
A43: 4号楼3&4车间 | B43: 助理工程师 | C43: 吴凯 | D43: ALS16007 | E43: 46043 | F43: =(L43*K43+G43+H43+I43-J43) -> 400 | G43: =SUMIF(积分汇总!$B:$B,'副主任&工艺组长及其他'!C43,积分汇总!$E:$E) -> 0 | H43: =SUMIF(记录巡查问题条数汇总!$B:$B,'副主任&工艺组长及其他'!C43,记录巡查问题条数汇总!$E:$E) -> 0 | J43: =SUMIF(安全质量事故!$B:$B,'副主任&工艺组长及其他'!C43,安全质量事故!$G:$G) -> 0 | K43: 1 | L43: =HLOOKUP(M43,$A$143:$H$144,2) -> 400 | M43: B | Q43: 师傅 皮轶杰；调实验室学习制备 | R43: =VLOOKUP(D43,[1]生产部!$C:$C,1,0) -> ALS16007
...

Sheet 一线人员
A1: 车间 | B1: 职务 | C1: 姓名 | D1: 员工编号 | E1: 入职日期 | F1: 实际奖金合计 | G1: 日常巡查扣款 | H1: 记录巡查扣款 | I1: 定点摄影最佳区域和最差区域评比 | J1: 安全事故扣款 | K1: 5S日检奖金合计 | L1: 07月 | AQ1: 4#楼1&2车间“a、b、c”分布情况
L2: 46204 | M2: 46205 | N2: 46206 | O2: 46207 | P2: 46208 | Q2: 46209 | R2: 46210 | S2: 46211 | T2: 46212 | U2: 46213 | V2: 46214 | W2: 46215 | X2: 46216 | Y2: 46217 | Z2: 46218 | AA2: 46219 | AB2: 46220 | AC2: 46221 | AD2: 46222 | AE2: 46223 | AF2: 46224 | AG2: 46225 | AH2: 46226 | AI2: 46227 | AJ2: 46228 | AK2: 46229 | AL2: 46230 | AM2: 46231 | AN2: 46232 | AO2: 46233 | AP2: 46234 | AQ2: “a”占比 | AR2: “b”占比 | AS2: “c”占比 | AT2: 核对1 | AU2: 核对2
A3: 4号楼1&2车间 | B3: 工程师 | C3: 陈玉慧 | D3: ALS12990 | E3: 45462 | F3: =(K3+G3+H3+I3-J3) -> 0 | G3: =SUMIF(积分汇总!$B:$B,C3,积分汇总!$E:$E) -> 0 | H3: =SUMIF(记录巡查问题条数汇总!$B:$B,C3,记录巡查问题条数汇总!$E:$E) -> 0 | J3: =SUMIF(安全质量事故!$B:$B,C3,安全质量事故!$G:$G) -> 0 | K3: =COUNTIF(L3:AP3,标准数据!$A$2)*标准数据!$B$2+COUNTIF(L3:AP3,标准数据!$A$3)*标准数据!$B$3+COUNTIF(L3:AP3,标准数据!$A$4)*标准数据!$B$4 -> 0 | AQ3: =COUNTIF($L$3:$AP$73,"a") -> 0 | AR3: =COUNTIF($L$3:$AP$73,"b") -> 0 | AS3: =COUNTIF($L$3:$AP$73,"c") -> 0 | AT3: ALS12990 | AU3: 4号楼
B4: 工程师 | C4: 王宇亭 | D4: ALS14235 | E4: 45840 | F4: =(K4+G4+H4+I4-J4) -> 0 | G4: =SUMIF(积分汇总!$B:$B,C4,积分汇总!$E:$E) -> 0 | H4: =SUMIF(记录巡查问题条数汇总!$B:$B,C4,记录巡查问题条数汇总!$E:$E) -> 0 | J4: =SUMIF(安全质量事故!$B:$B,C4,安全质量事故!$G:$G) -> 0 | K4: =COUNTIF(L4:AP4,标准数据!$A$2)*标准数据!$B$2+COUNTIF(L4:AP4,标准数据!$A$3)*标准数据!$B$3+COUNTIF(L4:AP4,标准数据!$A$4)*标准数据!$B$4 -> 0 | AQ4: =AQ3/($AQ$3+$AR$3+$AS$3) -> #DIV/0! | AR4: =AR3/($AQ$3+$AR$3+$AS$3) -> #DIV/0! | AS4: =AS3/($AQ$3+$AR$3+$AS$3) -> #DIV/0! | AT4: ALS14235 | AU4: 4号楼1&2车间
B5: 工程师 | C5: 张政 | D5: ALS15334 | E5: 45980 | F5: =(K5+G5+H5+I5-J5) -> 0 | G5: =SUMIF(积分汇总!$B:$B,C5,积分汇总!$E:$E) -> 0 | H5: =SUMIF(记录巡查问题条数汇总!$B:$B,C5,记录巡查问题条数汇总!$E:$E) -> 0 | J5: =SUMIF(安全质量事故!$B:$B,C5,安全质量事故!$G:$G) -> 0 | K5: =COUNTIF(L5:AP5,标准数据!$A$2)*标准数据!$B$2+COUNTIF(L5:AP5,标准数据!$A$3)*标准数据!$B$3+COUNTIF(L5:AP5,标准数据!$A$4)*标准数据!$B$4 -> 0 | AT5: ALS15334 | AU5: 4号楼1&2车间
B6: 工程师 | C6: 杨晨 | D6: ALS15954 | E6: 46050 | F6: =(K6+G6+H6+I6-J6) -> 0 | G6: =SUMIF(积分汇总!$B:$B,C6,积分汇总!$E:$E) -> 0 | H6: =SUMIF(记录巡查问题条数汇总!$B:$B,C6,记录巡查问题条数汇总!$E:$E) -> 0 | J6: =SUMIF(安全质量事故!$B:$B,C6,安全质量事故!$G:$G) -> 0 | K6: =COUNTIF(L6:AP6,标准数据!$A$2)*标准数据!$B$2+COUNTIF(L6:AP6,标准数据!$A$3)*标准数据!$B$3+COUNTIF(L6:AP6,标准数据!$A$4)*标准数据!$B$4 -> 0 | AT6: ALS15954 | AU6: 4号楼1&2车间
B7: 工程师 | C7: 邵英强 | D7: ALS16808 | E7: 46153 | F7: =(K7+G7+H7+I7-J7) -> 0 | G7: =SUMIF(积分汇总!$B:$B,C7,积分汇总!$E:$E) -> 0 | H7: =SUMIF(记录巡查问题条数汇总!$B:$B,C7,记录巡查问题条数汇总!$E:$E) -> 0 | J7: =SUMIF(安全质量事故!$B:$B,C7,安全质量事故!$G:$G) -> 0 | K7: =COUNTIF(L7:AP7,标准数据!$A$2)*标准数据!$B$2+COUNTIF(L7:AP7,标准数据!$A$3)*标准数据!$B$3+COUNTIF(L7:AP7,标准数据!$A$4)*标准数据!$B$4 -> 0 | AT7: ALS16808 | AU7: 4号楼1&2车间
B8: 工程师 | C8: 郑昊 | D8: ALS11847 | E8: 45019 | F8: =(K8+G8+H8+I8-J8) -> 0 | G8: =SUMIF(积分汇总!$B:$B,C8,积分汇总!$E:$E) -> 0 | H8: =SUMIF(记录巡查问题条数汇总!$B:$B,C8,记录巡查问题条数汇总!$E:$E) -> 0 | J8: =SUMIF(安全质量事故!$B:$B,C8,安全质量事故!$G:$G) -> 0 | K8: =COUNTIF(L8:AP8,标准数据!$A$2)*标准数据!$B$2+COUNTIF(L8:AP8,标准数据!$A$3)*标准数据!$B$3+COUNTIF(L8:AP8,标准数据!$A$4)*标准数据!$B$4 -> 0 | AT8: ALS11847 | AU8: 4号楼1&2车间
B9: 班长 | C9: 苏谊 | D9: BDH0640 | E9: 44732 | F9: =(K9+G9+H9+I9-J9) -> 0 | G9: =SUMIF(积分汇总!$B:$B,C9,积分汇总!$E:$E) -> 0 | H9: =SUMIF(记录巡查问题条数汇总!$B:$B,C9,记录巡查问题条数汇总!$E:$E) -> 0 | J9: =SUMIF(安全质量事故!$B:$B,C9,安全质量事故!$G:$G) -> 0 | K9: =COUNTIF(L9:AP9,标准数据!$A$2)*标准数据!$B$2+COUNTIF(L9:AP9,标准数据!$A$3)*标准数据!$B$3+COUNTIF(L9:AP9,标准数据!$A$4)*标准数据!$B$4 -> 0 | AT9: BDH0640 | AU9: 4号楼1&2车间
B10: 班长 | C10: 胡强 | D10: ALS10148 | E10: 44755 | F10: =(K10+G10+H10+I10-J10) -> 0 | G10: =SUMIF(积分汇总!$B:$B,C10,积分汇总!$E:$E) -> 0 | H10: =SUMIF(记录巡查问题条数汇总!$B:$B,C10,记录巡查问题条数汇总!$E:$E) -> 0 | J10: =SUMIF(安全质量事故!$B:$B,C10,安全质量事故!$G:$G) -> 0 | K10: =COUNTIF(L10:AP10,标准数据!$A$2)*标准数据!$B$2+COUNTIF(L10:AP10,标准数据!$A$3)*标准数据!$B$3+COUNTIF(L10:AP10,标准数据!$A$4)*标准数据!$B$4 -> 0 | AT10: ALS10148 | AU10: 4号楼1&2车间
B11: 班长 | C11: 周玉凯 | D11: ALS11232 | E11: 44774 | F11: =(K11+G11+H11+I11-J11) -> 0 | G11: =SUMIF(积分汇总!$B:$B,C11,积分汇总!$E:$E) -> 0 | H11: =SUMIF(记录巡查问题条数汇总!$B:$B,C11,记录巡查问题条数汇总!$E:$E) -> 0 | J11: =SUMIF(安全质量事故!$B:$B,C11,安全质量事故!$G:$G) -> 0 | K11: =COUNTIF(L11:AP11,标准数据!$A$2)*标准数据!$B$2+COUNTIF(L11:AP11,标准数据!$A$3)*标准数据!$B$3+COUNTIF(L11:AP11,标准数据!$A$4)*标准数据!$B$4 -> 0 | AT11: ALS11232 | AU11: 4号楼1&2车间
B12: 助工 | C12: 刘栋 | D12: ALS11215 | E12: 44774 | F12: =(K12+G12+H12+I12-J12) -> 0 | G12: =SUMIF(积分汇总!$B:$B,C12,积分汇总!$E:$E) -> 0 | H12: =SUMIF(记录巡查问题条数汇总!$B:$B,C12,记录巡查问题条数汇总!$E:$E) -> 0 | J12: =SUMIF(安全质量事故!$B:$B,C12,安全质量事故!$G:$G) -> 0 | K12: =COUNTIF(L12:AP12,标准数据!$A$2)*标准数据!$B$2+COUNTIF(L12:AP12,标准数据!$A$3)*标准数据!$B$3+COUNTIF(L12:AP12,标准数据!$A$4)*标准数据!$B$4 -> 0 | AT12: ALS11215 | AU12: 4号楼1&2车间
B13: 助工 | C13: 张昊（ALS11789） | D13: ALS11789 | E13: 44998 | F13: =(K13+G13+H13+I13-J13) -> 0 | G13: =SUMIF(积分汇总!$B:$B,C13,积分汇总!$E:$E) -> 0 | H13: =SUMIF(记录巡查问题条数汇总!$B:$B,C13,记录巡查问题条数汇总!$E:$E) -> 0 | J13: =SUMIF(安全质量事故!$B:$B,C13,安全质量事故!$G:$G) -> 0 | K13: =COUNTIF(L13:AP13,标准数据!$A$2)*标准数据!$B$2+COUNTIF(L13:AP13,标准数据!$A$3)*标准数据!$B$3+COUNTIF(L13:AP13,标准数据!$A$4)*标准数据!$B$4 -> 0 | AT13: ALS11789 | AU13: 4号楼1&2车间
B14: 助工 | C14: 张鹏飞 | D14: ALS11846 | E14: 45019 | F14: =(K14+G14+H14+I14-J14) -> 0 | G14: =SUMIF(积分汇总!$B:$B,C14,积分汇总!$E:$E) -> 0 | H14: =SUMIF(记录巡查问题条数汇总!$B:$B,C14,记录巡查问题条数汇总!$E:$E) -> 0 | J14: =SUMIF(安全质量事故!$B:$B,C14,安全质量事故!$G:$G) -> 0 | K14: =COUNTIF(L14:AP14,标准数据!$A$2)*标准数据!$B$2+COUNTIF(L14:AP14,标准数据!$A$3)*标准数据!$B$3+COUNTIF(L14:AP14,标准数据!$A$4)*标准数据!$B$4 -> 0 | AT14: ALS11846 | AU14: 4号楼1&2车间
B15: 助工 | C15: 范锺铭 | D15: ALS12311 | E15: 45138 | F15: =(K15+G15+H15+I15-J15) -> 0 | G15: =SUMIF(积分汇总!$B:$B,C15,积分汇总!$E:$E) -> 0 | H15: =SUMIF(记录巡查问题条数汇总!$B:$B,C15,记录巡查问题条数汇总!$E:$E) -> 0 | J15: =SUMIF(安全质量事故!$B:$B,C15,安全质量事故!$G:$G) -> 0 | K15: =COUNTIF(L15:AP15,标准数据!$A$2)*标准数据!$B$2+COUNTIF(L15:AP15,标准数据!$A$3)*标准数据!$B$3+COUNTIF(L15:AP15,标准数据!$A$4)*标准数据!$B$4 -> 0 | AT15: ALS12311 | AU15: 4号楼1&2车间
B16: 助工 | C16: 朱永祺 | D16: ALS11786 | E16: 44998 | F16: =(K16+G16+H16+I16-J16) -> 0 | G16: =SUMIF(积分汇总!$B:$B,C16,积分汇总!$E:$E) -> 0 | H16: =SUMIF(记录巡查问题条数汇总!$B:$B,C16,记录巡查问题条数汇总!$E:$E) -> 0 | J16: =SUMIF(安全质量事故!$B:$B,C16,安全质量事故!$G:$G) -> 0 | K16: =COUNTIF(L16:AP16,标准数据!$A$2)*标准数据!$B$2+COUNTIF(L16:AP16,标准数据!$A$3)*标准数据!$B$3+COUNTIF(L16:AP16,标准数据!$A$4)*标准数据!$B$4 -> 0 | AT16: ALS11786 | AU16: 4号楼1&2车间
... B73: 操作工 | C73: 常文轩 | D73: ALS15398 | E73: 45980 | F73: =(K73+G73+H73+I73-J73) -> 0 | G73: =SUMIF(积分汇总!$B:$B,C73,积分汇总!$E:$E) -> 0 | H73: =SUMIF(记录巡查问题条数汇总!$B:$B,C73,记录巡查问题条数汇总!$E:$E) -> 0 | J73: =SUMIF(安全质量事故!$B:$B,C73,安全质量事故!$G:$G) -> 0 | K73: =COUNTIF(L73:AP73,标准数据!$A$2)*标准数据!$B$2+COUNTIF(L73:AP73,标准数据!$A$3)*标准数据!$B$3+COUNTIF(L73:AP73,标准数据!$A$4)*标准数据!$B$4 -> 0 | AT73: ALS15398 | AU73: 4号楼1&2车间
A74: 4号楼3&4车间 | B74: 工程师 | C74: 穆双超 | D74: ADH5432 | E74: 44752 | F74: =(K74+G74+H74+I74-J74) -> 0 | G74: =SUMIF(积分汇总!$B:$B,C74,积分汇总!$E:$E) -> 0 | H74: =SUMIF(记录巡查问题条数汇总!$B:$B,C74,记录巡查问题条数汇总!$E:$E) -> 0 | J74: =SUMIF(安全质量事故!$B:$B,C74,安全质量事故!$G:$G) -> 0 | K74: =COUNTIF(L74:AP74,标准数据!$A$2)*标准数据!$B$2+COUNTIF(L74:AP74,标准数据!$A$3)*标准数据!$B$3+COUNTIF(L74:AP74,标准数据!$A$4)*标准数据!$B$4 -> 0 | AQ74: 4#楼3&4车间“a、b、c”分布情况 | AT74: ADH5432 | AU74: 4号楼3&4车间
B75: 工程师 | C75: 于清凡 | D75: ALS5619 | E75: 43677 | F75: =(K75+G75+H75+I75-J75) -> 0 | G75: =SUMIF(积分汇总!$B:$B,C75,积分汇总!$E:$E) -> 0 | H75: =SUMIF(记录巡查问题条数汇总!$B:$B,C75,记录巡查问题条数汇总!$E:$E) -> 0 | J75: =SUMIF(安全质量事故!$B:$B,C75,安全质量事故!$G:$G) -> 0 | K75: =COUNTIF(L75:AP75,标准数据!$A$2)*标准数据!$B$2+COUNTIF(L75:AP75,标准数据!$A$3)*标准数据!$B$3+COUNTIF(L75:AP75,标准数据!$A$4)*标准数据!$B$4 -> 0 | AQ75: “a”占比 | AR75: “b”占比 | AS75: “c”占比 | AT75: ALS5619 | AU75: 4号楼3&4车间
B76: 工程师 | C76: 荣宪超 | D76: FX3085 | E76: 43977 | F76: =(K76+G76+H76+I76-J76) -> 0 | G76: =SUMIF(积分汇总!$B:$B,C76,积分汇总!$E:$E) -> 0 | H76: =SUMIF(记录巡查问题条数汇总!$B:$B,C76,记录巡查问题条数汇总!$E:$E) -> 0 | J76: =SUMIF(安全质量事故!$B:$B,C76,安全质量事故!$G:$G) -> 0 | K76: =COUNTIF(L76:AP76,标准数据!$A$2)*标准数据!$B$2+COUNTIF(L76:AP76,标准数据!$A$3)*标准数据!$B$3+COUNTIF(L76:AP76,标准数据!$A$4)*标准数据!$B$4 -> 0 | AQ76: =COUNTIF($L$74:$AP$164,"a") -> 0 | AR76: =COUNTIF($L$74:$AP$164,"b") -> 0 | AS76: =COUNTIF($L$74:$AP$164,"c") -> 0 | AT76: FX3085 | AU76: 4号楼3&4车间
B77: 工程师 | C77: 支庆 | D77: LFX569 | E77: 44389 | F77: =(K77+G77+H77+I77-J77) -> 0 | G77: =SUMIF(积分汇总!$B:$B,C77,积分汇总!$E:$E) -> 0 | H77: =SUMIF(记录巡查问题条数汇总!$B:$B,C77,记录巡查问题条数汇总!$E:$E) -> 0 | J77: =SUMIF(安全质量事故!$B:$B,C77,安全质量事故!$G:$G) -> 0 | K77: =COUNTIF(L77:AP77,标准数据!$A$2)*标准数据!$B$2+COUNTIF(L77:AP77,标准数据!$A$3)*标准数据!$B$3+COUNTIF(L77:AP77,标准数据!$A$4)*标准数据!$B$4 -> 0 | AQ77: =AQ76/($AQ$76+$AR$76+$AS$76) -> #DIV/0! | AR77: =AR76/($AQ$76+$AR$76+$AS$76) -> #DIV/0! | AS77: =AS76/($AQ$76+$AR$76+$AS$76) -> #DIV/0! | AT77: LFX569 | AU77: 4号楼3&4车间
B78: 工程师 | C78: 俞燕溪 | D78: ALS14328 | E78: 45847 | F78: =(K78+G78+H78+I78-J78) -> 0 | G78: =SUMIF(积分汇总!$B:$B,C78,积分汇总!$E:$E) -> 0 | H78: =SUMIF(记录巡查问题条数汇总!$B:$B,C78,记录巡查问题条数汇总!$E:$E) -> 0 | J78: =SUMIF(安全质量事故!$B:$B,C78,安全质量事故!$G:$G) -> 0 | K78: =COUNTIF(L78:AP78,标准数据!$A$2)*标准数据!$B$2+COUNTIF(L78:AP78,标准数据!$A$3)*标准数据!$B$3+COUNTIF(L78:AP78,标准数据!$A$4)*标准数据!$B$4 -> 0 | AT78: ALS14328 | AU78: 4号楼3&4车间
B79: 班长 | C79: 窦贤巩 | D79: ALS5807 | E79: 43817 | F79: =(K79+G79+H79+I79-J79) -> 0 | G79: =SUMIF(积分汇总!$B:$B,C79,积分汇总!$E:$E) -> 0 | H79: =SUMIF(记录巡查问题条数汇总!$B:$B,C79,记录巡查问题条数汇总!$E:$E) -> 0 | J79: =SUMIF(安全质量事故!$B:$B,C79,安全质量事故!$G:$G) -> 0 | K79: =COUNTIF(L79:AP79,标准数据!$A$2)*标准数据!$B$2+COUNTIF(L79:AP79,标准数据!$A$3)*标准数据!$B$3+COUNTIF(L79:AP79,标准数据!$A$4)*标准数据!$B$4 -> 0 | AT79: ALS5807 | AU79: 4号楼3&4车间
B80: 班长 | C80: 李董明 | D80: ALS10327 | E80: 44734 | F80: =(K80+G80+H80+I80-J80) -> 0 | G80: =SUMIF(积分汇总!$B:$B,C80,积分汇总!$E:$E) -> 0 | H80: =SUMIF(记录巡查问题条数汇总!$B:$B,C80,记录巡查问题条数汇总!$E:$E) -> 0 | J80: =SUMIF(安全质量事故!$B:$B,C80,安全质量事故!$G:$G) -> 0 | K80: =COUNTIF(L80:AP80,标准数据!$A$2)*标准数据!$B$2+COUNTIF(L80:AP80,标准数据!$A$3)*标准数据!$B$3+COUNTIF(L80:AP80,标准数据!$A$4)*标准数据!$B$4 -> 0 | AT80: ALS10327 | AU80: 4号楼3&4车间
B81: 班长 | C81: 王永乐 | D81: ALS10165 | E81: 44755 | F81: =(K81+G81+H81+I81-J81) -> 0 | G81: =SUMIF(积分汇总!$B:$B,C81,积分汇总!$E:$E) -> 0 | H81: =SUMIF(记录巡查问题条数汇总!$B:$B,C81,记录巡查问题条数汇总!$E:$E) -> 0 | J81: =SUMIF(安全质量事故!$B:$B,C81,安全质量事故!$G:$G) -> 0 | K81: =COUNTIF(L81:AP81,标准数据!$A$2)*标准数据!$B$2+COUNTIF(L81:AP81,标准数据!$A$3)*标准数据!$B$3+COUNTIF(L81:AP81,标准数据!$A$4)*标准数据!$B$4 -> 0 | AT81: ALS10165 | AU81: 4号楼3&4车间
B82: 班长 | C82: 韩德玉 | D82: ALS11936 | E82: 45056 | F82: =(K82+G82+H82+I82-J82) -> 0 | G82: =SUMIF(积分汇总!$B:$B,C82,积分汇总!$E:$E) -> 0 | H82: =SUMIF(记录巡查问题条数汇总!$B:$B,C82,记录巡查问题条数汇总!$E:$E) -> 0 | J82: =SUMIF(安全质量事故!$B:$B,C82,安全质量事故!$G:$G) -> 0 | K82: =COUNTIF(L82:AP82,标准数据!$A$2)*标准数据!$B$2+COUNTIF(L82:AP82,标准数据!$A$3)*标准数据!$B$3+COUNTIF(L82:AP82,标准数据!$A$4)*标准数据!$B$4 -> 0 | AT82: ALS11936 | AU82: 4号楼3&4车间
B83: 班长 | C83: 赵鹏帅 | D83: ALS10175 | E83: 44755 | F83: =(K83+G83+H83+I83-J83) -> 0 | G83: =SUMIF(积分汇总!$B:$B,C83,积分汇总!$E:$E) -> 0 | H83: =SUMIF(记录巡查问题条数汇总!$B:$B,C83,记录巡查问题条数汇总!$E:$E) -> 0 | J83: =SUMIF(安全质量事故!$B:$B,C83,安全质量事故!$G:$G) -> 0 | K83: =COUNTIF(L83:AP83,标准数据!$A$2)*标准数据!$B$2+COUNTIF(L83:AP83,标准数据!$A$3)*标准数据!$B$3+COUNTIF(L83:AP83,标准数据!$A$4)*标准数据!$B$4 -> 0 | AT83: ALS10175 | AU83: 4号楼3&4车间
B84: 班长 | C84: 李孝辉 | D84: ALS8328 | E84: 44454 | F84: =(K84+G84+H84+I84-J84) -> 0 | G84: =SUMIF(积分汇总!$B:$B,C84,积分汇总!$E:$E) -> 0 | H84: =SUMIF(记录巡查问题条数汇总!$B:$B,C84,记录巡查问题条数汇总!$E:$E) -> 0 | J84: =SUMIF(安全质量事故!$B:$B,C84,安全质量事故!$G:$G) -> 0 | K84: =COUNTIF(L84:AP84,标准数据!$A$2)*标准数据!$B$2+COUNTIF(L84:AP84,标准数据!$A$3)*标准数据!$B$3+COUNTIF(L84:AP84,标准数据!$A$4)*标准数据!$B$4 -> 0 | AT84: ALS8328 | AU84: 4号楼3&4车间
B85: 助工 | C85: 王嘉伟 | D85: ALS11236 | E85: 44774 | F85: =(K85+G85+H85+I85-J85) -> 0 | G85: =SUMIF(积分汇总!$B:$B,C85,积分汇总!$E:$E) -> 0 | H85: =SUMIF(记录巡查问题条数汇总!$B:$B,C85,记录巡查问题条数汇总!$E:$E) -> 0 | J85: =SUMIF(安全质量事故!$B:$B,C85,安全质量事故!$G:$G) -> 0 | K85: =COUNTIF(L85:AP85,标准数据!$A$2)*标准数据!$B$2+COUNTIF(L85:AP85,标准数据!$A$3)*标准数据!$B$3+COUNTIF(L85:AP85,标准数据!$A$4)*标准数据!$B$4 -> 0 | AT85: ALS11236 | AU85: 4号楼3&4车间
B86: 助工 | C86: 刘俊杰 | D86: ALS10335 | E86: 44734 | F86: =(K86+G86+H86+I86-J86) -> 0 | G86: =SUMIF(积分汇总!$B:$B,C86,积分汇总!$E:$E) -> 0 | H86: =SUMIF(记录巡查问题条数汇总!$B:$B,C86,记录巡查问题条数汇总!$E:$E) -> 0 | J86: =SUMIF(安全质量事故!$B:$B,C86,安全质量事故!$G:$G) -> 0 | K86: =COUNTIF(L86:AP86,标准数据!$A$2)*标准数据!$B$2+COUNTIF(L86:AP86,标准数据!$A$3)*标准数据!$B$3+COUNTIF(L86:AP86,标准数据!$A$4)*标准数据!$B$4 -> 0 | AT86: ALS10335 | AU86: 4号楼3&4车间
B87: 助工 | C87: 杨贺龙 | D87: ALS10317 | E87: 44734 | F87: =(K87+G87+H87+I87-J87) -> 0 | G87: =SUMIF(积分汇总!$B:$B,C87,积分汇总!$E:$E) -> 0 | H87: =SUMIF(记录巡查问题条数汇总!$B:$B,C87,记录巡查问题条数汇总!$E:$E) -> 0 | J87: =SUMIF(安全质量事故!$B:$B,C87,安全质量事故!$G:$G) -> 0 | K87: =COUNTIF(L87:AP87,标准数据!$A$2)*标准数据!$B$2+COUNTIF(L87:AP87,标准数据!$A$3)*标准数据!$B$3+COUNTIF(L87:AP87,标准数据!$A$4)*标准数据!$B$4 -> 0 | AT87: ALS10317 | AU87: 4号楼3&4车间
B88: 助工 | C88: 肖王宇 | D88: ALS10328 | E88: 44734 | F88: =(K88+G88+H88+I88-J88) -> 0 | G88: =SUMIF(积分汇总!$B:$B,C88,积分汇总!$E:$E) -> 0 | H88: =SUMIF(记录巡查问题条数汇总!$B:$B,C88,记录巡查问题条数汇总!$E:$E) -> 0 | J88: =SUMIF(安全质量事故!$B:$B,C88,安全质量事故!$G:$G) -> 0 | K88: =COUNTIF(L88:AP88,标准数据!$A$2)*标准数据!$B$2+COUNTIF(L88:AP88,标准数据!$A$3)*标准数据!$B$3+COUNTIF(L88:AP88,标准数据!$A$4)*标准数据!$B$4 -> 0 | AT88: ALS10328 | AU88: 4号楼3&4车间
B89: 助工 | C89: 卫森豪 | D89: ALS11226 | E89: 44774 | F89: =(K89+G89+H89+I89-J89) -> 0 | G89: =SUMIF(积分汇总!$B:$B,C89,积分汇总!$E:$E) -> 0 | H89: =SUMIF(记录巡查问题条数汇总!$B:$B,C89,记录巡查问题条数汇总!$E:$E) -> 0 | J89: =SUMIF(安全质量事故!$B:$B,C89,安全质量事故!$G:$G) -> 0 | K89: =COUNTIF(L89:AP89,标准数据!$A$2)*标准数据!$B$2+COUNTIF(L89:AP89,标准数据!$A$3)*标准数据!$B$3+COUNTIF(L89:AP89,标准数据!$A$4)*标准数据!$B$4 -> 0 | AT89: ALS11226 | AU89: 4号楼3&4车间
... B164: 操作工 | C164: 石教炀 | D164: ALS15575 | E164: 45994 | F164: =(K164+G164+H164+I164-J164) -> 0 | G164: =SUMIF(积分汇总!$B:$B,C164,积分汇总!$E:$E) -> 0 | H164: =SUMIF(记录巡查问题条数汇总!$B:$B,C164,记录巡查问题条数汇总!$E:$E) -> 0 | J164: =SUMIF(安全质量事故!$B:$B,C164,安全质量事故!$G:$G) -> 0 | K164: =COUNTIF(L164:AP164,标准数据!$A$2)*标准数据!$B$2+COUNTIF(L164:AP164,标准数据!$A$3)*标准数据!$B$3+COUNTIF(L164:AP164,标准数据!$A$4)*标准数据!$B$4 -> 0 | AT164: ALS15575 | AU164: 4号楼3&4车间
A165: 11号楼CNC车间 | B165: 工程师 | C165: 李文笑 | D165: ALS12304 | E165: 45138 | F165: =(K165+G165+H165+I165-J165) -> 0 | G165: =SUMIF(积分汇总!$B:$B,C165,积分汇总!$E:$E) -> 0 | H165: =SUMIF(记录巡查问题条数汇总!$B:$B,C165,记录巡查问题条数汇总!$E:$E) -> 0 | J165: =SUMIF(安全质量事故!$B:$B,C165,安全质量事故!$G:$G) -> 0 | K165: =COUNTIF(L165:AP165,标准数据!$A$2)*标准数据!$B$2+COUNTIF(L165:AP165,标准数据!$A$3)*标准数据!$B$3+COUNTIF(L165:AP165,标准数据!$A$4)*标准数据!$B$4 -> 0 | AQ165: 11号楼CNC车间“a、b、c”分布情况 | AT165: ALS12304 | AU165: 11号楼CNC区域
B166: 工程师 | C166: 王继鹏 | D166: ALS14314 | E166: 45847 | F166: =(K166+G166+H166+I166-J166) -> 0 | G166: =SUMIF(积分汇总!$B:$B,C166,积分汇总!$E:$E) -> 0 | H166: =SUMIF(记录巡查问题条数汇总!$B:$B,C166,记录巡查问题条数汇总!$E:$E) -> 0 | J166: =SUMIF(安全质量事故!$B:$B,C166,安全质量事故!$G:$G) -> 0 | K166: =COUNTIF(L166:AP166,标准数据!$A$2)*标准数据!$B$2+COUNTIF(L166:AP166,标准数据!$A$3)*标准数据!$B$3+COUNTIF(L166:AP166,标准数据!$A$4)*标准数据!$B$4 -> 0 | AQ166: “a”占比 | AR166: “b”占比 | AS166: “c”占比 | AT166: ALS14314 | AU166: 11号楼CNC区域
B167: 助工 | C167: 赵柯达 | D167: ALS13177 | E167: 45490 | F167: =(K167+G167+H167+I167-J167) -> 0 | G167: =SUMIF(积分汇总!$B:$B,C167,积分汇总!$E:$E) -> 0 | H167: =SUMIF(记录巡查问题条数汇总!$B:$B,C167,记录巡查问题条数汇总!$E:$E) -> 0 | J167: =SUMIF(安全质量事故!$B:$B,C167,安全质量事故!$G:$G) -> 0 | K167: =COUNTIF(L167:AP167,标准数据!$A$2)*标准数据!$B$2+COUNTIF(L167:AP167,标准数据!$A$3)*标准数据!$B$3+COUNTIF(L167:AP167,标准数据!$A$4)*标准数据!$B$4 -> 0 | AQ167: =COUNTIF($L$165:$AP$226,"a") -> 0 | AR167: =COUNTIF($L$165:$AP$226,"b") -> 0 | AS167: =COUNTIF($L$165:$AP$226,"c") -> 0 | AT167: ALS13177 | AU167: 11号楼CNC区域
B168: 助工 | C168: 张泽 | D168: ALS13027 | E168: 45469 | F168: =(K168+G168+H168+I168-J168) -> 0 | G168: =SUMIF(积分汇总!$B:$B,C168,积分汇总!$E:$E) -> 0 | H168: =SUMIF(记录巡查问题条数汇总!$B:$B,C168,记录巡查问题条数汇总!$E:$E) -> 0 | J168: =SUMIF(安全质量事故!$B:$B,C168,安全质量事故!$G:$G) -> 0 | K168: =COUNTIF(L168:AP168,标准数据!$A$2)*标准数据!$B$2+COUNTIF(L168:AP168,标准数据!$A$3)*标准数据!$B$3+COUNTIF(L168:AP168,标准数据!$A$4)*标准数据!$B$4 -> 0 | AQ168: =AQ167/($AQ$167+$AR$167+$AS$167) -> #DIV/0! | AR168: =AR167/($AQ$167+$AR$167+$AS$167) -> #DIV/0! | AS168: =AS167/($AQ$167+$AR$167+$AS$167) -> #DIV/0! | AT168: ALS13027 | AU168: 11号楼CNC区域
B169: 班长 | C169: 张博（ALS0034） | D169: ALS0034 | E169: 38548 | F169: =(K169+G169+H169+I169-J169) -> 0 | G169: =SUMIF(积分汇总!$B:$B,C169,积分汇总!$E:$E) -> 0 | H169: =SUMIF(记录巡查问题条数汇总!$B:$B,C169,记录巡查问题条数汇总!$E:$E) -> 0 | J169: =SUMIF(安全质量事故!$B:$B,C169,安全质量事故!$G:$G) -> 0 | K169: =COUNTIF(L169:AP169,标准数据!$A$2)*标准数据!$B$2+COUNTIF(L169:AP169,标准数据!$A$3)*标准数据!$B$3+COUNTIF(L169:AP169,标准数据!$A$4)*标准数据!$B$4 -> 0 | AT169: ALS0034 | AU169: 11号楼CNC区域
B170: 班长 | C170: 查超山 | D170: ALS11201 | E170: 44774 | F170: =(K170+G170+H170+I170-J170) -> 0 | G170: =SUMIF(积分汇总!$B:$B,C170,积分汇总!$E:$E) -> 0 | H170: =SUMIF(记录巡查问题条数汇总!$B:$B,C170,记录巡查问题条数汇总!$E:$E) -> 0 | J170: =SUMIF(安全质量事故!$B:$B,C170,安全质量事故!$G:$G) -> 0 | K170: =COUNTIF(L170:AP170,标准数据!$A$2)*标准数据!$B$2+COUNTIF(L170:AP170,标准数据!$A$3)*标准数据!$B$3+COUNTIF(L170:AP170,标准数据!$A$4)*标准数据!$B$4 -> 0 | AT170: ALS11201 | AU170: 11号楼CNC区域
...

Sheet 复核人
A1: 4#楼1&2车间：田志勇 | B1: 刘其琛
A2: 4#楼3&4车间： 刘磊
A3: 4号楼制备组：皮轶杰
A4: 11#楼CNC车间：门学友 | B4: 杜永宝
A5: 11#楼D级区：梁光强/李晓刚
A6: 5号楼：冯恩利 | B6: 魏鹏
A7: 12号楼：代海鑫 | B7: 姜彬
A8: 验证组 / DCS / 电子设备维护 / 合规&培训 ： 刘亚南 | B8: 刘亚南
A9: 环保设备设施 ：刘文龙 | B9: 刘文龙
A10: 外围/罐区/泵房：赵艳春/吴宗璇
A11: 清洗组： 陈正兴
A12: 安全组 | B12: 李国清
A13: 生产技术转移组（辅料&毒素连接体） | B13: 刘其琛
A14: 生产技术转移组（多肽） | B14: 蔡森
A15: 13号楼 | B15: 李子凯

Sheet 说明
A1: 数据提供人 | B1: 安全质量奖 | C1: 一线人员sheet | D1: 副主任sheet
B2: 4#楼1&2车间： | C2: 田志勇 | D2: 刘其琛
B3: 4#楼3&4车间： | C3: 刘磊
B4: 11#楼CNC车间： | C4: 门学友 | D4: 杜永宝
B5: 11#楼D级区： | C5: 梁光强
B6: 5号楼： | C6: 冯恩利 | D6: 魏鹏
B7: 12号楼： | C7: 代海鑫 | D7: 姜彬
B8: 验证组 / DCS / 电子设备维护 / 合规&培训 ： | C8: 刘亚南 | D8: 刘亚南
B9: 环保设备设施 ： | C9: 刘文龙
B10: 外围/罐区/泵房： | C10: 赵艳春
B11: 清洗组： | C11: 陈正兴
B12: 安全组 | D12: 李国清
A13: 汇总说明
A14: 1 | B14: 月末或者月初整理安全质量奖，一线人员sheet和副主任sheet人员用员工编号与月底的人员明细表核对，删除离职的，补充新入职的人员；将日期修改后，内容清空，发给对应提报人，提供评价
A15: 2 | B15: 副主任级别sheet，添加好后面的设备使用率及对应挡位，钉钉发给对应该管理人员，问挡位是否有调整
A16: 3 | B16: 调生产设备部的不用管，调实验室的备注，调TJ1的加到TJ1核算表中

Sheet 积分汇总
A1: 积分汇总
A2: 车间 | B2: 姓名 | C2: 违规 | D2: 奖励 | E2: 积分合计 | F2: 备注
E3: =C3+D3 -> 0
E4: =C4+D4 -> 0
E5: =C5+D5 -> 0
E6: =C6+D6 -> 0
E7: =C7+D7 -> 0
E8: =C8+D8 -> 0
E9: =C9+D9 -> 0
E10: =C10+D10 -> 0
E11: =C11+D11 -> 0
E12: =C12+D12 -> 0
E13: =C13+D13 -> 0
E14: =C14+D14 -> 0
... E48: =C48+D48 -> 0
C49: =SUM(C3:C48) -> 0 | D49: =SUM(D3:D48) -> 0 | E49: =C49+D49 -> 0

Sheet 安全质量事故
A1: 车间 | B1: 责任人 | C1: 来源类别 | D1: 编号 | E1: 事故描述 | F1: 奖惩结果 | G1: 奖金扣除

Sheet 记录巡查问题条数汇总
A1: 车间 | B1: 姓名 | C1: 巡查条数汇总 | D1: 积分 | E1: 安全质量奖扣款

Sheet 标准数据
A1: 档位 | B1: 标准奖金 | C1: 人员占比
A2: A | B2: 35 | C2: 0.2
A3: B | B3: 15 | C3: 0.6
A4: C | B4: -5 | C4: 0.2
A10: 有API项目生产时，进入API工作的人员安全质量奖额外增加200元.
A11: >> 仅限一线人员(助工).
